2022-09-11 11:15:05,819 : INFO : root : Loading config.
2022-09-11 11:15:05,822 : INFO : YamlMultifileConfigLoader : Machine config file #1: config.yaml
2022-09-11 11:15:05,823 : INFO : ConfigProcessor : Loading config from cache: C:\Users\dorus\AppData\Local\Temp\0aa359e6326ef14bcc36d32fc9dec35b.mpf_cache
2022-09-11 11:15:05,824 : WARNING : ConfigProcessor : Config file in cache changed: C:\pinball\mpfv1\config\hardware.yaml
2022-09-11 11:15:05,824 : INFO : ConfigProcessor : Loading config from file C:\Users\dorus\AppData\Local\Programs\Python\Python38\lib\site-packages\mpf\mpfconfig.yaml.
2022-09-11 11:15:05,883 : INFO : ConfigProcessor : Loading config: C:\Users\dorus\AppData\Local\Programs\Python\Python38\lib\site-packages\mpf\mpfconfig.yaml
2022-09-11 11:15:05,884 : INFO : ConfigProcessor : Loading config from file C:\pinball\mpfv1\config\config.yaml.
2022-09-11 11:15:05,886 : INFO : ConfigProcessor : Loading config: C:\pinball\mpfv1\config\config.yaml
2022-09-11 11:15:05,911 : INFO : ConfigProcessor : Loading config: C:\pinball\mpfv1\config\hardware.yaml
2022-09-11 11:15:05,920 : INFO : ConfigProcessor : Loading config: C:\pinball\mpfv1\config\sounds.yaml
2022-09-11 11:15:05,923 : INFO : ConfigProcessor : Loading config: C:\pinball\mpfv1\config\display.yaml
2022-09-11 11:15:05,930 : INFO : ConfigProcessor : Loading config: C:\pinball\mpfv1\config\keyboard.yaml
2022-09-11 11:15:05,932 : INFO : ConfigProcessor : Config file cache created: C:\Users\dorus\AppData\Local\Temp\0aa359e6326ef14bcc36d32fc9dec35b.mpf_cache
2022-09-11 11:15:06,016 : INFO : ConfigProcessor : Loading config from cache: C:\Users\dorus\AppData\Local\Temp\5eb3439dbf16142704b5198a23e9a58c.mpf_cache
2022-09-11 11:15:06,018 : INFO : ConfigProcessor : Loading config from cache: C:\Users\dorus\AppData\Local\Temp\336e6d2601ccb63523c70814805acbf1.mpf_cache
2022-09-11 11:15:06,019 : INFO : ConfigProcessor : Loading config from cache: C:\Users\dorus\AppData\Local\Temp\d4952d0b9ea6ba2ec58a4f9adbee2d8a.mpf_cache
2022-09-11 11:15:06,020 : INFO : ConfigProcessor : Loading config from cache: C:\Users\dorus\AppData\Local\Temp\f88a77831ebd1fc65525f08072013dbd.mpf_cache
2022-09-11 11:15:06,020 : INFO : Machine : Mission Pinball Framework Core Engine v0.55.0
2022-09-11 11:15:06,020 : INFO : Machine : Command line arguments: {'no_load_cache': False, 'create_config_cache': True, 'bcp': True, 'configfile': ['config.yaml'], 'force_assets_load': False, 'jsonlogging': False, 'logfile': 'logs\\2022-09-11-11-15-05-mpf-LAPTOP-AS8QDAQG.log', 'pause': False, 'production': False, 'text_ui': True, 'loglevel': 15, 'consoleloglevel': 20, 'force_platform': None, 'syslog_address': None, 'mc_file_name': None, 'no_sound': False}
2022-09-11 11:15:06,021 : INFO : Machine : MPF path: C:\Users\dorus\AppData\Local\Programs\Python\Python38\lib\site-packages\mpf
2022-09-11 11:15:06,021 : INFO : Machine : Machine path: C:\pinball\mpfv1
2022-09-11 11:15:06,021 : INFO : Machine : Platform: win32
2022-09-11 11:15:06,021 : INFO : Machine : Python executable location: C:\Users\dorus\AppData\Local\Programs\Python\Python38\python.exe
2022-09-11 11:15:06,021 : INFO : Machine : Python version: 3.8.10 (64-bit)
2022-09-11 11:15:06,022 : INFO : Machine : Initialise MPF.
2022-09-11 11:15:06,179 : INFO : OPP : Connecting to COM7 at 115200bps
2022-09-11 11:15:06,266 : INFO : OPP : Init of OPP board COM7 done
2022-09-11 11:15:06,267 : INFO : EventManager : Event: ======'machine_var_credits_string'====== Args={'value': 'FREE PLAY', 'prev_value': None, 'change': True}
2022-09-11 11:15:06,315 : INFO : EventManager : Event: ======'machine_var_master_volume'====== Args={'value': 0.5, 'prev_value': None, 'change': True}
2022-09-11 11:15:06,315 : INFO : EventManager : Event: ======'machine_var_player1_score'====== Args={'value': 39900, 'prev_value': None, 'change': True}
2022-09-11 11:15:06,316 : INFO : EventManager : Event: ======'machine_var_mpf_version'====== Args={'value': 'MPF v0.55.0', 'prev_value': None, 'change': True}
2022-09-11 11:15:06,316 : INFO : EventManager : Event: ======'machine_var_mpf_extended_version'====== Args={'value': 'MPF v0.55.0, Config version:5, Show version: 5, BCP version:1.1', 'prev_value': None, 'change': True}
2022-09-11 11:15:06,316 : INFO : EventManager : Event: ======'machine_var_python_version'====== Args={'value': '3.8.10', 'prev_value': None, 'change': True}
2022-09-11 11:15:06,325 : INFO : EventManager : Event: ======'machine_var_platform'====== Args={'value': 'Windows-10-10.0.19044-SP0', 'prev_value': None, 'change': True}
2022-09-11 11:15:06,326 : INFO : EventManager : Event: ======'machine_var_platform_system'====== Args={'value': 'Windows', 'prev_value': None, 'change': True}
2022-09-11 11:15:06,326 : INFO : EventManager : Event: ======'machine_var_platform_release'====== Args={'value': '10', 'prev_value': None, 'change': True}
2022-09-11 11:15:06,326 : INFO : EventManager : Event: ======'machine_var_platform_version'====== Args={'value': '10.0.19044', 'prev_value': None, 'change': True}
2022-09-11 11:15:06,326 : INFO : EventManager : Event: ======'machine_var_platform_machine'====== Args={'value': 'AMD64', 'prev_value': None, 'change': True}
2022-09-11 11:15:06,326 : INFO : EventManager : Event: ======'init_phase_1'====== Args={}
2022-09-11 11:15:06,348 : INFO : EventManager : Event: ======'drop_target_bank_db_dropbank_up'====== Args={}
2022-09-11 11:15:06,350 : INFO : EventManager : Event: ======'init_phase_2'====== Args={}
2022-09-11 11:15:06,350 : INFO : SwitchController : Found active switch: ('COM7-0-25', <Platform.OPP>) <switch.s_trough_jam>
2022-09-11 11:15:06,353 : INFO : EventManager : Event: ======'bcp_connection_attempt'====== Args={'name': 'local_display', 'host': 'localhost', 'port': 5050}
2022-09-11 11:15:06,355 : INFO : BCPClientSocket : Connecting BCP to 'local_display' at localhost:5050...
2022-09-11 11:15:08,388 : INFO : BCPClientSocket : Connected BCP to 'local_display' localhost:5050
2022-09-11 11:15:08,389 : INFO : EventManager : Event: ======'bcp_clients_connected'====== Args={}
2022-09-11 11:15:08,398 : INFO : ball_device.bd_trough : BCH: Count is unstable. Trying to reorder balls.
2022-09-11 11:15:08,399 : WARNING : ball_device.bd_trough : Cannot reorder device because eject_coil_reorder_pulse is not configured
2022-09-11 11:15:08,399 : INFO : ball_device.bd_trough : BCH: Repulse done. Waiting for balls to settle.
2022-09-11 11:15:08,399 : INFO : ball_device.bd_trough : BCH: Initial count: 1
2022-09-11 11:15:08,400 : INFO : EventManager : Event: ======'machine_var_mc_version'====== Args={'value': 'MPF-MC v0.55.0', 'prev_value': None, 'change': True}
2022-09-11 11:15:08,400 : INFO : EventManager : Event: ======'machine_var_mc_extended_version'====== Args={'value': 'MPF-MC v0.55.0 (config_version=5, BCP v1.1, Requires MPF v0.55.0-dev.49)', 'prev_value': None, 'change': True}
2022-09-11 11:15:08,404 : INFO : ball_device.bd_trough : State: idle
2022-09-11 11:15:08,414 : INFO : ball_device.bd_plunger : BCH: Initial count: 0
2022-09-11 11:15:08,414 : INFO : ball_device.bd_plunger : State: idle
2022-09-11 11:15:08,415 : ERROR : asyncio : Task exception was never retrieved
future: <Task finished name='Task-99' coro=<BallDevice._initialize_async() done, defined at C:\Users\dorus\AppData\Local\Programs\Python\Python38\lib\site-packages\mpf\devices\ball_device\ball_device.py:195> exception=ConfigFileError('Config validation error: Entry ball_device_counter_ball_switches:ball_device_counter_ball_switches:ball_switches = "s_vuk1" is not valid. Device "s_vuk1" not found in "switches:" section in your config.')>
Traceback (most recent call last):
  File "C:\Users\dorus\AppData\Local\Programs\Python\Python38\lib\site-packages\mpf\devices\ball_device\ball_device.py", line 197, in _initialize_async
    await self.ball_count_handler.initialise()
  File "C:\Users\dorus\AppData\Local\Programs\Python\Python38\lib\site-packages\mpf\devices\ball_device\ball_count_handler.py", line 92, in initialise
    self.counter = counter_class(self.ball_device, self.ball_device.config.get("counter", {}))
  File "C:\Users\dorus\AppData\Local\Programs\Python\Python38\lib\site-packages\mpf\devices\ball_device\switch_counter.py", line 27, in __init__
    self.config = self.machine.config_validator.validate_config("ball_device_counter_ball_switches", self.config)
  File "C:\Users\dorus\AppData\Local\Programs\Python\Python38\lib\site-packages\mpf\core\config_validator.py", line 179, in validate_config
    return self._validate_config(config_spec, source, base_spec=base_spec, add_missing_keys=add_missing_keys,
  File "C:\Users\dorus\AppData\Local\Programs\Python\Python38\lib\site-packages\mpf\core\config_validator.py", line 220, in _validate_config
    processed_config[k] = self.validate_config_item(
  File "C:\Users\dorus\AppData\Local\Programs\Python\Python38\lib\site-packages\mpf\core\config_validator.py", line 272, in validate_config_item
    new_list.append(self.validate_item(i, validation, validation_failure_info))
  File "C:\Users\dorus\AppData\Local\Programs\Python\Python38\lib\site-packages\mpf\core\config_validator.py", line 709, in validate_item
    return self.validator_list[validator](item, validation_failure_info=validation_failure_info, param=param)
  File "C:\Users\dorus\AppData\Local\Programs\Python\Python38\lib\site-packages\mpf\core\config_validator.py", line 422, in _validate_type_machine
    return self.validation_error(item, validation_failure_info,
  File "C:\Users\dorus\AppData\Local\Programs\Python\Python38\lib\site-packages\mpf\core\config_validator.py", line 726, in validation_error
    raise ConfigFileError("Config validation error: Entry {} = \"{}\" is not valid. {}".format(
mpf.exceptions.config_file_error.ConfigFileError: Config File Error in ConfigValidator: Config validation error: Entry ball_device_counter_ball_switches:ball_device_counter_ball_switches:ball_switches = "s_vuk1" is not valid. Device "s_vuk1" not found in "switches:" section in your config. Error Code: CFE-ConfigValidator-6 (https://docs.missionpinball.org/en/0.55/logs/CFE-ConfigValidator-6.html)
2022-09-11 11:15:08,468 : ERROR : asyncio : Task exception was never retrieved
future: <Task finished name='Task-100' coro=<BallDevice._initialize_async() done, defined at C:\Users\dorus\AppData\Local\Programs\Python\Python38\lib\site-packages\mpf\devices\ball_device\ball_device.py:195> exception=ConfigFileError('Config validation error: Entry ball_device_counter_ball_switches:ball_device_counter_ball_switches:ball_switches = "s_vuk2" is not valid. Device "s_vuk2" not found in "switches:" section in your config.')>
Traceback (most recent call last):
  File "C:\Users\dorus\AppData\Local\Programs\Python\Python38\lib\site-packages\mpf\devices\ball_device\ball_device.py", line 197, in _initialize_async
    await self.ball_count_handler.initialise()
  File "C:\Users\dorus\AppData\Local\Programs\Python\Python38\lib\site-packages\mpf\devices\ball_device\ball_count_handler.py", line 92, in initialise
    self.counter = counter_class(self.ball_device, self.ball_device.config.get("counter", {}))
  File "C:\Users\dorus\AppData\Local\Programs\Python\Python38\lib\site-packages\mpf\devices\ball_device\switch_counter.py", line 27, in __init__
    self.config = self.machine.config_validator.validate_config("ball_device_counter_ball_switches", self.config)
  File "C:\Users\dorus\AppData\Local\Programs\Python\Python38\lib\site-packages\mpf\core\config_validator.py", line 179, in validate_config
    return self._validate_config(config_spec, source, base_spec=base_spec, add_missing_keys=add_missing_keys,
  File "C:\Users\dorus\AppData\Local\Programs\Python\Python38\lib\site-packages\mpf\core\config_validator.py", line 220, in _validate_config
    processed_config[k] = self.validate_config_item(
  File "C:\Users\dorus\AppData\Local\Programs\Python\Python38\lib\site-packages\mpf\core\config_validator.py", line 272, in validate_config_item
    new_list.append(self.validate_item(i, validation, validation_failure_info))
  File "C:\Users\dorus\AppData\Local\Programs\Python\Python38\lib\site-packages\mpf\core\config_validator.py", line 709, in validate_item
    return self.validator_list[validator](item, validation_failure_info=validation_failure_info, param=param)
  File "C:\Users\dorus\AppData\Local\Programs\Python\Python38\lib\site-packages\mpf\core\config_validator.py", line 422, in _validate_type_machine
    return self.validation_error(item, validation_failure_info,
  File "C:\Users\dorus\AppData\Local\Programs\Python\Python38\lib\site-packages\mpf\core\config_validator.py", line 726, in validation_error
    raise ConfigFileError("Config validation error: Entry {} = \"{}\" is not valid. {}".format(
mpf.exceptions.config_file_error.ConfigFileError: Config File Error in ConfigValidator: Config validation error: Entry ball_device_counter_ball_switches:ball_device_counter_ball_switches:ball_switches = "s_vuk2" is not valid. Device "s_vuk2" not found in "switches:" section in your config. Error Code: CFE-ConfigValidator-6 (https://docs.missionpinball.org/en/0.55/logs/CFE-ConfigValidator-6.html)
2022-09-11 11:15:08,469 : INFO : Machine : Starting the main run loop.
2022-09-11 11:15:08,555 : INFO : EventManager : Event: ======'init_phase_3'====== Args={}
2022-09-11 11:15:08,558 : INFO : Machine : Shutting down...
2022-09-11 11:15:08,559 : INFO : EventManager : Event: ======'shutdown'====== Args={}
2022-09-11 11:15:08,567 : ERROR : asyncio : Exception in callback EventManager._queue_task_done(<Task finishe...y not found')>)
handle: <Handle EventManager._queue_task_done(<Task finishe...y not found')>)>
Traceback (most recent call last):
  File "C:\Users\dorus\AppData\Local\Programs\Python\Python38\lib\asyncio\events.py", line 81, in _run
    self._context.run(self._callback, *self._args)
  File "C:\Users\dorus\AppData\Local\Programs\Python\Python38\lib\site-packages\mpf\core\events.py", line 728, in _queue_task_done
    future.result()
  File "C:\Users\dorus\AppData\Local\Programs\Python\Python38\lib\site-packages\mpf\core\events.py", line 645, in _run_handlers_sequential
    handler.callback(queue=queue, **merged_kwargs)
  File "C:\Users\dorus\AppData\Local\Programs\Python\Python38\lib\site-packages\mpf\core\config_player.py", line 83, in _initialise_system_wide
    self.register_player_events(
  File "C:\Users\dorus\AppData\Local\Programs\Python\Python38\lib\site-packages\mpf\config_players\plugin_player.py", line 55, in register_player_events
    self.bcp_client = self._get_bcp_client(config)
  File "C:\Users\dorus\AppData\Local\Programs\Python\Python38\lib\site-packages\mpf\config_players\plugin_player.py", line 33, in _get_bcp_client
    raise AssertionError(
AssertionError: bcp connection local_display not found
2022-09-11 11:15:08,613 : ERROR : OPP : Stop called on serial connection COM7
2022-09-11 11:15:08,616 : ERROR : Machine : Runtime Exception
Traceback (most recent call last):
  File "C:\Users\dorus\AppData\Local\Programs\Python\Python38\lib\site-packages\mpf\core\machine.py", line 769, in _run_loop
    raise self._exception['exception']
  File "C:\Users\dorus\AppData\Local\Programs\Python\Python38\lib\site-packages\mpf\devices\ball_device\ball_device.py", line 197, in _initialize_async
    await self.ball_count_handler.initialise()
  File "C:\Users\dorus\AppData\Local\Programs\Python\Python38\lib\site-packages\mpf\devices\ball_device\ball_count_handler.py", line 92, in initialise
    self.counter = counter_class(self.ball_device, self.ball_device.config.get("counter", {}))
  File "C:\Users\dorus\AppData\Local\Programs\Python\Python38\lib\site-packages\mpf\devices\ball_device\switch_counter.py", line 27, in __init__
    self.config = self.machine.config_validator.validate_config("ball_device_counter_ball_switches", self.config)
  File "C:\Users\dorus\AppData\Local\Programs\Python\Python38\lib\site-packages\mpf\core\config_validator.py", line 179, in validate_config
    return self._validate_config(config_spec, source, base_spec=base_spec, add_missing_keys=add_missing_keys,
  File "C:\Users\dorus\AppData\Local\Programs\Python\Python38\lib\site-packages\mpf\core\config_validator.py", line 220, in _validate_config
    processed_config[k] = self.validate_config_item(
  File "C:\Users\dorus\AppData\Local\Programs\Python\Python38\lib\site-packages\mpf\core\config_validator.py", line 272, in validate_config_item
    new_list.append(self.validate_item(i, validation, validation_failure_info))
  File "C:\Users\dorus\AppData\Local\Programs\Python\Python38\lib\site-packages\mpf\core\config_validator.py", line 709, in validate_item
    return self.validator_list[validator](item, validation_failure_info=validation_failure_info, param=param)
  File "C:\Users\dorus\AppData\Local\Programs\Python\Python38\lib\site-packages\mpf\core\config_validator.py", line 422, in _validate_type_machine
    return self.validation_error(item, validation_failure_info,
  File "C:\Users\dorus\AppData\Local\Programs\Python\Python38\lib\site-packages\mpf\core\config_validator.py", line 726, in validation_error
    raise ConfigFileError("Config validation error: Entry {} = \"{}\" is not valid. {}".format(
mpf.exceptions.config_file_error.ConfigFileError: Config File Error in ConfigValidator: Config validation error: Entry ball_device_counter_ball_switches:ball_device_counter_ball_switches:ball_switches = "s_vuk1" is not valid. Device "s_vuk1" not found in "switches:" section in your config. Error Code: CFE-ConfigValidator-6 (https://docs.missionpinball.org/en/0.55/logs/CFE-ConfigValidator-6.html)
2022-09-11 11:16:39,647 : INFO : root : MPF run loop ended.
