2022-09-16 14:49:30,857 : INFO : root : Loading config.
2022-09-16 14:49:30,860 : INFO : YamlMultifileConfigLoader : Machine config file #1: config.yaml
2022-09-16 14:49:30,861 : INFO : ConfigProcessor : Loading config from cache: C:\Users\dorus\AppData\Local\Temp\0aa359e6326ef14bcc36d32fc9dec35b.mpf_cache
2022-09-16 14:49:30,869 : WARNING : ConfigProcessor : Config file in cache changed: C:\pinball\mpfv1\config\hardware.yaml
2022-09-16 14:49:30,869 : INFO : ConfigProcessor : Loading config from file C:\Users\dorus\AppData\Local\Programs\Python\Python38\lib\site-packages\mpf\mpfconfig.yaml.
2022-09-16 14:49:30,923 : INFO : ConfigProcessor : Loading config: C:\Users\dorus\AppData\Local\Programs\Python\Python38\lib\site-packages\mpf\mpfconfig.yaml
2022-09-16 14:49:30,923 : INFO : ConfigProcessor : Loading config from file C:\pinball\mpfv1\config\config.yaml.
2022-09-16 14:49:30,926 : INFO : ConfigProcessor : Loading config: C:\pinball\mpfv1\config\config.yaml
2022-09-16 14:49:30,952 : INFO : ConfigProcessor : Loading config: C:\pinball\mpfv1\config\hardware.yaml
2022-09-16 14:49:30,960 : INFO : ConfigProcessor : Loading config: C:\pinball\mpfv1\config\sounds.yaml
2022-09-16 14:49:30,964 : INFO : ConfigProcessor : Loading config: C:\pinball\mpfv1\config\display.yaml
2022-09-16 14:49:30,971 : INFO : ConfigProcessor : Loading config: C:\pinball\mpfv1\config\keyboard.yaml
2022-09-16 14:49:30,974 : INFO : ConfigProcessor : Config file cache created: C:\Users\dorus\AppData\Local\Temp\0aa359e6326ef14bcc36d32fc9dec35b.mpf_cache
2022-09-16 14:49:31,096 : INFO : ConfigProcessor : Loading config from cache: C:\Users\dorus\AppData\Local\Temp\5eb3439dbf16142704b5198a23e9a58c.mpf_cache
2022-09-16 14:49:31,106 : INFO : ConfigProcessor : Loading config from cache: C:\Users\dorus\AppData\Local\Temp\336e6d2601ccb63523c70814805acbf1.mpf_cache
2022-09-16 14:49:31,112 : INFO : ConfigProcessor : Loading config from cache: C:\Users\dorus\AppData\Local\Temp\d4952d0b9ea6ba2ec58a4f9adbee2d8a.mpf_cache
2022-09-16 14:49:31,119 : INFO : ConfigProcessor : Loading config from cache: C:\Users\dorus\AppData\Local\Temp\f88a77831ebd1fc65525f08072013dbd.mpf_cache
2022-09-16 14:49:31,125 : INFO : Machine : Mission Pinball Framework Core Engine v0.55.0
2022-09-16 14:49:31,125 : INFO : Machine : Command line arguments: {'no_load_cache': False, 'create_config_cache': True, 'bcp': True, 'configfile': ['config.yaml'], 'force_assets_load': False, 'jsonlogging': False, 'logfile': 'logs\\2022-09-16-14-49-30-mpf-LAPTOP-AS8QDAQG.log', 'pause': False, 'production': False, 'text_ui': True, 'loglevel': 15, 'consoleloglevel': 20, 'force_platform': None, 'syslog_address': None, 'mc_file_name': None, 'no_sound': False}
2022-09-16 14:49:31,125 : INFO : Machine : MPF path: C:\Users\dorus\AppData\Local\Programs\Python\Python38\lib\site-packages\mpf
2022-09-16 14:49:31,125 : INFO : Machine : Machine path: C:\pinball\mpfv1
2022-09-16 14:49:31,125 : INFO : Machine : Platform: win32
2022-09-16 14:49:31,125 : INFO : Machine : Python executable location: C:\Users\dorus\AppData\Local\Programs\Python\Python38\python.exe
2022-09-16 14:49:31,125 : INFO : Machine : Python version: 3.8.10 (64-bit)
2022-09-16 14:49:31,128 : INFO : Machine : Initialise MPF.
2022-09-16 14:49:31,437 : INFO : OPP : Connecting to COM7 at 115200bps
2022-09-16 14:49:31,443 : INFO : Machine : Shutting down...
2022-09-16 14:49:31,443 : INFO : EventManager : Event: ======'shutdown'====== Args={}
2022-09-16 14:49:31,444 : ERROR : Machine : Failed to initialise MPF
Traceback (most recent call last):
  File "C:\Users\dorus\AppData\Local\Programs\Python\Python38\lib\site-packages\mpf\core\machine.py", line 673, in initialise_mpf
    raise init.exception()
  File "C:\Users\dorus\AppData\Local\Programs\Python\Python38\lib\site-packages\mpf\core\machine.py", line 244, in initialise
    await self.initialise_core_and_hardware()
  File "C:\Users\dorus\AppData\Local\Programs\Python\Python38\lib\site-packages\mpf\core\machine.py", line 240, in initialise_core_and_hardware
    await self._initialize_platforms()
  File "C:\Users\dorus\AppData\Local\Programs\Python\Python38\lib\site-packages\mpf\core\machine.py", line 331, in _initialize_platforms
    result.result()
  File "C:\Users\dorus\AppData\Local\Programs\Python\Python38\lib\site-packages\mpf\platforms\opp\opp.py", line 105, in initialize
    await self._connect_to_hardware()
  File "C:\Users\dorus\AppData\Local\Programs\Python\Python38\lib\site-packages\mpf\platforms\opp\opp.py", line 278, in _connect_to_hardware
    await comm.connect()
  File "C:\Users\dorus\AppData\Local\Programs\Python\Python38\lib\site-packages\mpf\platforms\base_serial_communicator.py", line 45, in connect
    await self._connect_to_hardware(self.port, self.baud, self.xonxoff)
  File "C:\Users\dorus\AppData\Local\Programs\Python\Python38\lib\site-packages\mpf\platforms\base_serial_communicator.py", line 54, in _connect_to_hardware
    self.reader, self.writer = await connector
  File "C:\Users\dorus\AppData\Local\Programs\Python\Python38\lib\site-packages\mpf\core\clock.py", line 152, in open_serial_connection
    transport, _ = await create_serial_connection(
  File "C:\Users\dorus\AppData\Local\Programs\Python\Python38\lib\asyncio\coroutines.py", line 124, in coro
    res = func(*args, **kw)
  File "C:\Users\dorus\AppData\Local\Programs\Python\Python38\lib\site-packages\serial_asyncio\__init__.py", line 410, in create_serial_connection
    ser = serial.serial_for_url(*args, **kwargs)
  File "C:\Users\dorus\AppData\Local\Programs\Python\Python38\lib\site-packages\serial\__init__.py", line 90, in serial_for_url
    instance.open()
  File "C:\Users\dorus\AppData\Local\Programs\Python\Python38\lib\site-packages\serial\serialwin32.py", line 64, in open
    raise SerialException("could not open port {!r}: {!r}".format(self.portstr, ctypes.WinError()))
serial.serialutil.SerialException: could not open port 'COM7': FileNotFoundError(2, 'The system cannot find the file specified.', None, 2)
2022-09-16 14:49:44,619 : ERROR : root : 
Traceback (most recent call last):
  File "C:\Users\dorus\AppData\Local\Programs\Python\Python38\lib\site-packages\mpf\core\machine.py", line 673, in initialise_mpf
    raise init.exception()
  File "C:\Users\dorus\AppData\Local\Programs\Python\Python38\lib\site-packages\mpf\core\machine.py", line 244, in initialise
    await self.initialise_core_and_hardware()
  File "C:\Users\dorus\AppData\Local\Programs\Python\Python38\lib\site-packages\mpf\core\machine.py", line 240, in initialise_core_and_hardware
    await self._initialize_platforms()
  File "C:\Users\dorus\AppData\Local\Programs\Python\Python38\lib\site-packages\mpf\core\machine.py", line 331, in _initialize_platforms
    result.result()
  File "C:\Users\dorus\AppData\Local\Programs\Python\Python38\lib\site-packages\mpf\platforms\opp\opp.py", line 105, in initialize
    await self._connect_to_hardware()
  File "C:\Users\dorus\AppData\Local\Programs\Python\Python38\lib\site-packages\mpf\platforms\opp\opp.py", line 278, in _connect_to_hardware
    await comm.connect()
  File "C:\Users\dorus\AppData\Local\Programs\Python\Python38\lib\site-packages\mpf\platforms\base_serial_communicator.py", line 45, in connect
    await self._connect_to_hardware(self.port, self.baud, self.xonxoff)
  File "C:\Users\dorus\AppData\Local\Programs\Python\Python38\lib\site-packages\mpf\platforms\base_serial_communicator.py", line 54, in _connect_to_hardware
    self.reader, self.writer = await connector
  File "C:\Users\dorus\AppData\Local\Programs\Python\Python38\lib\site-packages\mpf\core\clock.py", line 152, in open_serial_connection
    transport, _ = await create_serial_connection(
  File "C:\Users\dorus\AppData\Local\Programs\Python\Python38\lib\asyncio\coroutines.py", line 124, in coro
    res = func(*args, **kw)
  File "C:\Users\dorus\AppData\Local\Programs\Python\Python38\lib\site-packages\serial_asyncio\__init__.py", line 410, in create_serial_connection
    ser = serial.serial_for_url(*args, **kwargs)
  File "C:\Users\dorus\AppData\Local\Programs\Python\Python38\lib\site-packages\serial\__init__.py", line 90, in serial_for_url
    instance.open()
  File "C:\Users\dorus\AppData\Local\Programs\Python\Python38\lib\site-packages\serial\serialwin32.py", line 64, in open
    raise SerialException("could not open port {!r}: {!r}".format(self.portstr, ctypes.WinError()))
serial.serialutil.SerialException: could not open port 'COM7': FileNotFoundError(2, 'The system cannot find the file specified.', None, 2)

During handling of the above exception, another exception occurred:

Traceback (most recent call last):
  File "C:\Users\dorus\AppData\Local\Programs\Python\Python38\lib\site-packages\mpf\commands\game.py", line 239, in __init__
    self.machine.run()
  File "C:\Users\dorus\AppData\Local\Programs\Python\Python38\lib\site-packages\mpf\core\machine.py", line 683, in run
    if not self.initialise_mpf():
  File "C:\Users\dorus\AppData\Local\Programs\Python\Python38\lib\site-packages\mpf\core\machine.py", line 676, in initialise_mpf
    report_crash(init.exception(), "init_exception", self.config)
  File "C:\Users\dorus\AppData\Local\Programs\Python\Python38\lib\site-packages\mpf\core\crash_reporter.py", line 236, in report_crash
    response = input("Do you want to report the crash to the MPF team (yes/no/show)? ")
EOFError
