2022-10-16 17:09:21,511 : INFO : root : Loading config.
2022-10-16 17:09:21,515 : INFO : YamlMultifileConfigLoader : Machine config file #1: config.yaml
2022-10-16 17:09:21,515 : INFO : ConfigProcessor : Loading config from file C:\Users\dorus\AppData\Local\Programs\Python\Python38\lib\site-packages\mpf\mpfconfig.yaml.
2022-10-16 17:09:21,574 : INFO : ConfigProcessor : Loading config: C:\Users\dorus\AppData\Local\Programs\Python\Python38\lib\site-packages\mpf\mpfconfig.yaml
2022-10-16 17:09:21,574 : INFO : ConfigProcessor : Loading config from file C:\pinball\Pinball-MPF\Incantest\config\config.yaml.
2022-10-16 17:09:21,599 : INFO : ConfigProcessor : Loading config: C:\pinball\Pinball-MPF\Incantest\config\config.yaml
2022-10-16 17:09:21,601 : INFO : ConfigProcessor : Config file cache created: C:\Users\dorus\AppData\Local\Temp\2933e2c76e3b8acea895e42efa05d46f.mpf_cache
2022-10-16 17:09:21,732 : INFO : ConfigProcessor : Loading config from file C:\Users\dorus\AppData\Local\Programs\Python\Python38\lib\site-packages\mpf\modes\attract\config\attract.yaml.
2022-10-16 17:09:21,739 : INFO : ConfigProcessor : Loading config: C:\Users\dorus\AppData\Local\Programs\Python\Python38\lib\site-packages\mpf\modes\attract\config\attract.yaml
2022-10-16 17:09:21,739 : INFO : ConfigProcessor : Loading config from file C:\pinball\Pinball-MPF\Incantest\modes\attract\config\attract.yaml.
2022-10-16 17:09:21,741 : INFO : ConfigProcessor : Loading config: C:\pinball\Pinball-MPF\Incantest\modes\attract\config\attract.yaml
2022-10-16 17:09:21,742 : INFO : ConfigProcessor : Config file cache created: C:\Users\dorus\AppData\Local\Temp\00c75b6024e2fe2e03aca7195f2ab2ac.mpf_cache
2022-10-16 17:09:21,743 : INFO : ConfigProcessor : Loading config from file C:\Users\dorus\AppData\Local\Programs\Python\Python38\lib\site-packages\mpf\modes\game\config\game.yaml.
2022-10-16 17:09:21,749 : INFO : ConfigProcessor : Loading config: C:\Users\dorus\AppData\Local\Programs\Python\Python38\lib\site-packages\mpf\modes\game\config\game.yaml
2022-10-16 17:09:21,750 : INFO : ConfigProcessor : Config file cache created: C:\Users\dorus\AppData\Local\Temp\336e6d2601ccb63523c70814805acbf1.mpf_cache
2022-10-16 17:09:21,751 : INFO : ConfigProcessor : Loading config from file C:\pinball\Pinball-MPF\Incantest\modes\base\config\base.yaml.
2022-10-16 17:09:21,758 : INFO : ConfigProcessor : Loading config: C:\pinball\Pinball-MPF\Incantest\modes\base\config\base.yaml
2022-10-16 17:09:21,758 : INFO : ConfigProcessor : Config file cache created: C:\Users\dorus\AppData\Local\Temp\2bf6cf40d54a5ac6b43f4cbd4b4344a2.mpf_cache
2022-10-16 17:09:21,760 : INFO : ConfigProcessor : Loading config from file C:\pinball\Pinball-MPF\Incantest\modes\attract\shows\.\attract_display_loop.yaml.
2022-10-16 17:09:21,766 : INFO : ConfigProcessor : Loading config: C:\pinball\Pinball-MPF\Incantest\modes\attract\shows\.\attract_display_loop.yaml
2022-10-16 17:09:21,766 : INFO : ConfigProcessor : Config file cache created: C:\Users\dorus\AppData\Local\Temp\e44e93bdfc9f543212586de2e62675d1.mpf_cache
2022-10-16 17:09:21,767 : INFO : Machine : Mission Pinball Framework Core Engine v0.55.0
2022-10-16 17:09:21,767 : INFO : Machine : Command line arguments: {'no_load_cache': False, 'create_config_cache': True, 'bcp': True, 'configfile': ['config.yaml'], 'force_assets_load': False, 'jsonlogging': False, 'logfile': 'logs\\2022-10-16-17-09-21-mpf-LAPTOP-AS8QDAQG.log', 'pause': False, 'production': False, 'text_ui': True, 'loglevel': 15, 'consoleloglevel': 20, 'force_platform': None, 'syslog_address': None, 'mc_file_name': None, 'no_sound': False}
2022-10-16 17:09:21,767 : INFO : Machine : MPF path: C:\Users\dorus\AppData\Local\Programs\Python\Python38\lib\site-packages\mpf
2022-10-16 17:09:21,767 : INFO : Machine : Machine path: C:\pinball\Pinball-MPF\Incantest
2022-10-16 17:09:21,767 : INFO : Machine : Platform: win32
2022-10-16 17:09:21,767 : INFO : Machine : Python executable location: C:\Users\dorus\AppData\Local\Programs\Python\Python38\python.exe
2022-10-16 17:09:21,767 : INFO : Machine : Python version: 3.8.10 (64-bit)
2022-10-16 17:09:21,769 : INFO : Machine : Initialise MPF.
2022-10-16 17:09:22,038 : INFO : OPP : Connecting to COM7 at 115200bps
2022-10-16 17:09:22,132 : INFO : OPP : Init of OPP board COM7 done
2022-10-16 17:09:22,132 : INFO : EventManager : Event: ======'machine_var_credits_string'====== Args={'value': 'FREE PLAY', 'prev_value': None, 'change': True}
2022-10-16 17:09:22,195 : INFO : EventManager : Event: ======'machine_var_master_volume'====== Args={'value': 0.5, 'prev_value': None, 'change': True}
2022-10-16 17:09:22,195 : INFO : EventManager : Event: ======'machine_var_mpf_version'====== Args={'value': 'MPF v0.55.0', 'prev_value': None, 'change': True}
2022-10-16 17:09:22,195 : INFO : EventManager : Event: ======'machine_var_mpf_extended_version'====== Args={'value': 'MPF v0.55.0, Config version:5, Show version: 5, BCP version:1.1', 'prev_value': None, 'change': True}
2022-10-16 17:09:22,195 : INFO : EventManager : Event: ======'machine_var_python_version'====== Args={'value': '3.8.10', 'prev_value': None, 'change': True}
2022-10-16 17:09:22,207 : INFO : EventManager : Event: ======'machine_var_platform'====== Args={'value': 'Windows-10-10.0.19044-SP0', 'prev_value': None, 'change': True}
2022-10-16 17:09:22,207 : INFO : EventManager : Event: ======'machine_var_platform_system'====== Args={'value': 'Windows', 'prev_value': None, 'change': True}
2022-10-16 17:09:22,207 : INFO : EventManager : Event: ======'machine_var_platform_release'====== Args={'value': '10', 'prev_value': None, 'change': True}
2022-10-16 17:09:22,207 : INFO : EventManager : Event: ======'machine_var_platform_version'====== Args={'value': '10.0.19044', 'prev_value': None, 'change': True}
2022-10-16 17:09:22,207 : INFO : EventManager : Event: ======'machine_var_platform_machine'====== Args={'value': 'AMD64', 'prev_value': None, 'change': True}
2022-10-16 17:09:22,207 : INFO : EventManager : Event: ======'init_phase_1'====== Args={}
2022-10-16 17:09:22,223 : INFO : EventManager : Event: ======'drop_target_bank_db_dropbank_up'====== Args={}
2022-10-16 17:09:22,223 : ERROR : asyncio : Task exception was never retrieved
future: <Task finished name='Task-49' coro=<SystemWideDevice.device_added_system_wide() done, defined at C:\Users\dorus\AppData\Local\Programs\Python\Python38\lib\site-packages\mpf\core\system_wide_device.py:15> exception=ConfigFileError('Failed to configure switch s_toplane3 in platform. See error above')>
Traceback (most recent call last):
  File "C:\Users\dorus\AppData\Local\Programs\Python\Python38\lib\site-packages\mpf\devices\switch.py", line 148, in _initialize
    self.hw_switch = self.platform.configure_switch(
  File "C:\Users\dorus\AppData\Local\Programs\Python\Python38\lib\site-packages\mpf\platforms\opp\opp.py", line 825, in configure_switch
    number = self._get_dict_index(number)
  File "C:\Users\dorus\AppData\Local\Programs\Python\Python38\lib\site-packages\mpf\platforms\opp\opp.py", line 770, in _get_dict_index
    self.raise_config_error("Chain {} does not exist. Existing chains: {}".format(
  File "C:\Users\dorus\AppData\Local\Programs\Python\Python38\lib\site-packages\mpf\core\logging.py", line 172, in raise_config_error
    raise ConfigFileError(msg, error_no, self.log.name if self.log else "", context, self._url_base) \
mpf.exceptions.config_file_error.ConfigFileError: Config File Error in OPP: Chain 1 does not exist. Existing chains: ['COM7'] Error Code: CFE-OPP-3 (https://docs.missionpinball.org/en/0.55/logs/CFE-OPP-3.html)

The above exception was the direct cause of the following exception:

Traceback (most recent call last):
  File "C:\Users\dorus\AppData\Local\Programs\Python\Python38\lib\site-packages\mpf\core\system_wide_device.py", line 17, in device_added_system_wide
    await self._initialize()
  File "C:\Users\dorus\AppData\Local\Programs\Python\Python38\lib\site-packages\mpf\devices\switch.py", line 151, in _initialize
    raise ConfigFileError("Failed to configure switch {} in platform. See error above".format(self.name), 2,
mpf.exceptions.config_file_error.ConfigFileError: Config File Error in switch: Failed to configure switch s_toplane3 in platform. See error above Error Code: CFE-switch-2 (https://docs.missionpinball.org/en/0.55/logs/CFE-switch-2.html)
2022-10-16 17:09:22,254 : ERROR : asyncio : Task exception was never retrieved
future: <Task finished name='Task-37' coro=<SystemWideDevice.device_added_system_wide() done, defined at C:\Users\dorus\AppData\Local\Programs\Python\Python38\lib\site-packages\mpf\core\system_wide_device.py:15> exception=ConfigFileError('Failed to configure switch s_popbumber_3 in platform. See error above')>
Traceback (most recent call last):
  File "C:\Users\dorus\AppData\Local\Programs\Python\Python38\lib\site-packages\mpf\devices\switch.py", line 148, in _initialize
    self.hw_switch = self.platform.configure_switch(
  File "C:\Users\dorus\AppData\Local\Programs\Python\Python38\lib\site-packages\mpf\platforms\opp\opp.py", line 825, in configure_switch
    number = self._get_dict_index(number)
  File "C:\Users\dorus\AppData\Local\Programs\Python\Python38\lib\site-packages\mpf\platforms\opp\opp.py", line 770, in _get_dict_index
    self.raise_config_error("Chain {} does not exist. Existing chains: {}".format(
  File "C:\Users\dorus\AppData\Local\Programs\Python\Python38\lib\site-packages\mpf\core\logging.py", line 172, in raise_config_error
    raise ConfigFileError(msg, error_no, self.log.name if self.log else "", context, self._url_base) \
mpf.exceptions.config_file_error.ConfigFileError: Config File Error in OPP: Chain 0 does not exist. Existing chains: ['COM7'] Error Code: CFE-OPP-3 (https://docs.missionpinball.org/en/0.55/logs/CFE-OPP-3.html)

The above exception was the direct cause of the following exception:

Traceback (most recent call last):
  File "C:\Users\dorus\AppData\Local\Programs\Python\Python38\lib\site-packages\mpf\core\system_wide_device.py", line 17, in device_added_system_wide
    await self._initialize()
  File "C:\Users\dorus\AppData\Local\Programs\Python\Python38\lib\site-packages\mpf\devices\switch.py", line 151, in _initialize
    raise ConfigFileError("Failed to configure switch {} in platform. See error above".format(self.name), 2,
mpf.exceptions.config_file_error.ConfigFileError: Config File Error in switch: Failed to configure switch s_popbumber_3 in platform. See error above Error Code: CFE-switch-2 (https://docs.missionpinball.org/en/0.55/logs/CFE-switch-2.html)
2022-10-16 17:09:22,254 : ERROR : asyncio : Task exception was never retrieved
future: <Task finished name='Task-25' coro=<SystemWideDevice.device_added_system_wide() done, defined at C:\Users\dorus\AppData\Local\Programs\Python\Python38\lib\site-packages\mpf\core\system_wide_device.py:15> exception=ConfigFileError('Failed to configure switch s_left_sling in platform. See error above')>
Traceback (most recent call last):
  File "C:\Users\dorus\AppData\Local\Programs\Python\Python38\lib\site-packages\mpf\devices\switch.py", line 148, in _initialize
    self.hw_switch = self.platform.configure_switch(
  File "C:\Users\dorus\AppData\Local\Programs\Python\Python38\lib\site-packages\mpf\platforms\opp\opp.py", line 825, in configure_switch
    number = self._get_dict_index(number)
  File "C:\Users\dorus\AppData\Local\Programs\Python\Python38\lib\site-packages\mpf\platforms\opp\opp.py", line 770, in _get_dict_index
    self.raise_config_error("Chain {} does not exist. Existing chains: {}".format(
  File "C:\Users\dorus\AppData\Local\Programs\Python\Python38\lib\site-packages\mpf\core\logging.py", line 172, in raise_config_error
    raise ConfigFileError(msg, error_no, self.log.name if self.log else "", context, self._url_base) \
mpf.exceptions.config_file_error.ConfigFileError: Config File Error in OPP: Chain 0 does not exist. Existing chains: ['COM7'] Error Code: CFE-OPP-3 (https://docs.missionpinball.org/en/0.55/logs/CFE-OPP-3.html)

The above exception was the direct cause of the following exception:

Traceback (most recent call last):
  File "C:\Users\dorus\AppData\Local\Programs\Python\Python38\lib\site-packages\mpf\core\system_wide_device.py", line 17, in device_added_system_wide
    await self._initialize()
  File "C:\Users\dorus\AppData\Local\Programs\Python\Python38\lib\site-packages\mpf\devices\switch.py", line 151, in _initialize
    raise ConfigFileError("Failed to configure switch {} in platform. See error above".format(self.name), 2,
mpf.exceptions.config_file_error.ConfigFileError: Config File Error in switch: Failed to configure switch s_left_sling in platform. See error above Error Code: CFE-switch-2 (https://docs.missionpinball.org/en/0.55/logs/CFE-switch-2.html)
2022-10-16 17:09:22,254 : ERROR : asyncio : Task exception was never retrieved
future: <Task finished name='Task-13' coro=<SystemWideDevice.device_added_system_wide() done, defined at C:\Users\dorus\AppData\Local\Programs\Python\Python38\lib\site-packages\mpf\core\system_wide_device.py:15> exception=ConfigFileError('Failed to configure switch s_launch in platform. See error above')>
Traceback (most recent call last):
  File "C:\Users\dorus\AppData\Local\Programs\Python\Python38\lib\site-packages\mpf\devices\switch.py", line 148, in _initialize
    self.hw_switch = self.platform.configure_switch(
  File "C:\Users\dorus\AppData\Local\Programs\Python\Python38\lib\site-packages\mpf\platforms\opp\opp.py", line 825, in configure_switch
    number = self._get_dict_index(number)
  File "C:\Users\dorus\AppData\Local\Programs\Python\Python38\lib\site-packages\mpf\platforms\opp\opp.py", line 770, in _get_dict_index
    self.raise_config_error("Chain {} does not exist. Existing chains: {}".format(
  File "C:\Users\dorus\AppData\Local\Programs\Python\Python38\lib\site-packages\mpf\core\logging.py", line 172, in raise_config_error
    raise ConfigFileError(msg, error_no, self.log.name if self.log else "", context, self._url_base) \
mpf.exceptions.config_file_error.ConfigFileError: Config File Error in OPP: Chain 0 does not exist. Existing chains: ['COM7'] Error Code: CFE-OPP-3 (https://docs.missionpinball.org/en/0.55/logs/CFE-OPP-3.html)

The above exception was the direct cause of the following exception:

Traceback (most recent call last):
  File "C:\Users\dorus\AppData\Local\Programs\Python\Python38\lib\site-packages\mpf\core\system_wide_device.py", line 17, in device_added_system_wide
    await self._initialize()
  File "C:\Users\dorus\AppData\Local\Programs\Python\Python38\lib\site-packages\mpf\devices\switch.py", line 151, in _initialize
    raise ConfigFileError("Failed to configure switch {} in platform. See error above".format(self.name), 2,
mpf.exceptions.config_file_error.ConfigFileError: Config File Error in switch: Failed to configure switch s_launch in platform. See error above Error Code: CFE-switch-2 (https://docs.missionpinball.org/en/0.55/logs/CFE-switch-2.html)
2022-10-16 17:09:22,254 : ERROR : asyncio : Task exception was never retrieved
future: <Task finished name='Task-38' coro=<SystemWideDevice.device_added_system_wide() done, defined at C:\Users\dorus\AppData\Local\Programs\Python\Python38\lib\site-packages\mpf\core\system_wide_device.py:15> exception=AssertionError('Failed to configure driver c_sling_right in platform. See error above')>
Traceback (most recent call last):
  File "C:\Users\dorus\AppData\Local\Programs\Python\Python38\lib\site-packages\mpf\devices\driver.py", line 107, in _initialize
    self.hw_driver = self.platform.configure_driver(config, self.config['number'], platform_settings)
  File "C:\Users\dorus\AppData\Local\Programs\Python\Python38\lib\site-packages\mpf\platforms\opp\opp.py", line 788, in configure_driver
    number = self._get_dict_index(number)
  File "C:\Users\dorus\AppData\Local\Programs\Python\Python38\lib\site-packages\mpf\platforms\opp\opp.py", line 770, in _get_dict_index
    self.raise_config_error("Chain {} does not exist. Existing chains: {}".format(
  File "C:\Users\dorus\AppData\Local\Programs\Python\Python38\lib\site-packages\mpf\core\logging.py", line 172, in raise_config_error
    raise ConfigFileError(msg, error_no, self.log.name if self.log else "", context, self._url_base) \
mpf.exceptions.config_file_error.ConfigFileError: Config File Error in OPP: Chain 0 does not exist. Existing chains: ['COM7'] Error Code: CFE-OPP-3 (https://docs.missionpinball.org/en/0.55/logs/CFE-OPP-3.html)

The above exception was the direct cause of the following exception:

Traceback (most recent call last):
  File "C:\Users\dorus\AppData\Local\Programs\Python\Python38\lib\site-packages\mpf\core\system_wide_device.py", line 17, in device_added_system_wide
    await self._initialize()
  File "C:\Users\dorus\AppData\Local\Programs\Python\Python38\lib\site-packages\mpf\devices\driver.py", line 109, in _initialize
    raise AssertionError("Failed to configure driver {} in platform. See error above".format(self.name)) from e
AssertionError: Failed to configure driver c_sling_right in platform. See error above
2022-10-16 17:09:22,254 : ERROR : asyncio : Task exception was never retrieved
future: <Task finished name='Task-63' coro=<SystemWideDevice.device_added_system_wide() done, defined at C:\Users\dorus\AppData\Local\Programs\Python\Python38\lib\site-packages\mpf\core\system_wide_device.py:15> exception=AssertionError('Failed to configure driver c_popbumper_3 in platform. See error above')>
Traceback (most recent call last):
  File "C:\Users\dorus\AppData\Local\Programs\Python\Python38\lib\site-packages\mpf\devices\driver.py", line 107, in _initialize
    self.hw_driver = self.platform.configure_driver(config, self.config['number'], platform_settings)
  File "C:\Users\dorus\AppData\Local\Programs\Python\Python38\lib\site-packages\mpf\platforms\opp\opp.py", line 788, in configure_driver
    number = self._get_dict_index(number)
  File "C:\Users\dorus\AppData\Local\Programs\Python\Python38\lib\site-packages\mpf\platforms\opp\opp.py", line 770, in _get_dict_index
    self.raise_config_error("Chain {} does not exist. Existing chains: {}".format(
  File "C:\Users\dorus\AppData\Local\Programs\Python\Python38\lib\site-packages\mpf\core\logging.py", line 172, in raise_config_error
    raise ConfigFileError(msg, error_no, self.log.name if self.log else "", context, self._url_base) \
mpf.exceptions.config_file_error.ConfigFileError: Config File Error in OPP: Chain 0 does not exist. Existing chains: ['COM7'] Error Code: CFE-OPP-3 (https://docs.missionpinball.org/en/0.55/logs/CFE-OPP-3.html)

The above exception was the direct cause of the following exception:

Traceback (most recent call last):
  File "C:\Users\dorus\AppData\Local\Programs\Python\Python38\lib\site-packages\mpf\core\system_wide_device.py", line 17, in device_added_system_wide
    await self._initialize()
  File "C:\Users\dorus\AppData\Local\Programs\Python\Python38\lib\site-packages\mpf\devices\driver.py", line 109, in _initialize
    raise AssertionError("Failed to configure driver {} in platform. See error above".format(self.name)) from e
AssertionError: Failed to configure driver c_popbumper_3 in platform. See error above
2022-10-16 17:09:22,254 : ERROR : asyncio : Task exception was never retrieved
future: <Task finished name='Task-51' coro=<SystemWideDevice.device_added_system_wide() done, defined at C:\Users\dorus\AppData\Local\Programs\Python\Python38\lib\site-packages\mpf\core\system_wide_device.py:15> exception=AssertionError('Failed to configure driver c_trough_eject in platform. See error above')>
Traceback (most recent call last):
  File "C:\Users\dorus\AppData\Local\Programs\Python\Python38\lib\site-packages\mpf\devices\driver.py", line 107, in _initialize
    self.hw_driver = self.platform.configure_driver(config, self.config['number'], platform_settings)
  File "C:\Users\dorus\AppData\Local\Programs\Python\Python38\lib\site-packages\mpf\platforms\opp\opp.py", line 788, in configure_driver
    number = self._get_dict_index(number)
  File "C:\Users\dorus\AppData\Local\Programs\Python\Python38\lib\site-packages\mpf\platforms\opp\opp.py", line 770, in _get_dict_index
    self.raise_config_error("Chain {} does not exist. Existing chains: {}".format(
  File "C:\Users\dorus\AppData\Local\Programs\Python\Python38\lib\site-packages\mpf\core\logging.py", line 172, in raise_config_error
    raise ConfigFileError(msg, error_no, self.log.name if self.log else "", context, self._url_base) \
mpf.exceptions.config_file_error.ConfigFileError: Config File Error in OPP: Chain 0 does not exist. Existing chains: ['COM7'] Error Code: CFE-OPP-3 (https://docs.missionpinball.org/en/0.55/logs/CFE-OPP-3.html)

The above exception was the direct cause of the following exception:

Traceback (most recent call last):
  File "C:\Users\dorus\AppData\Local\Programs\Python\Python38\lib\site-packages\mpf\core\system_wide_device.py", line 17, in device_added_system_wide
    await self._initialize()
  File "C:\Users\dorus\AppData\Local\Programs\Python\Python38\lib\site-packages\mpf\devices\driver.py", line 109, in _initialize
    raise AssertionError("Failed to configure driver {} in platform. See error above".format(self.name)) from e
AssertionError: Failed to configure driver c_trough_eject in platform. See error above
2022-10-16 17:09:22,254 : ERROR : asyncio : Task exception was never retrieved
future: <Task finished name='Task-26' coro=<SystemWideDevice.device_added_system_wide() done, defined at C:\Users\dorus\AppData\Local\Programs\Python\Python38\lib\site-packages\mpf\core\system_wide_device.py:15> exception=ConfigFileError('Failed to configure switch s_left02 in platform. See error above')>
Traceback (most recent call last):
  File "C:\Users\dorus\AppData\Local\Programs\Python\Python38\lib\site-packages\mpf\devices\switch.py", line 148, in _initialize
    self.hw_switch = self.platform.configure_switch(
  File "C:\Users\dorus\AppData\Local\Programs\Python\Python38\lib\site-packages\mpf\platforms\opp\opp.py", line 825, in configure_switch
    number = self._get_dict_index(number)
  File "C:\Users\dorus\AppData\Local\Programs\Python\Python38\lib\site-packages\mpf\platforms\opp\opp.py", line 770, in _get_dict_index
    self.raise_config_error("Chain {} does not exist. Existing chains: {}".format(
  File "C:\Users\dorus\AppData\Local\Programs\Python\Python38\lib\site-packages\mpf\core\logging.py", line 172, in raise_config_error
    raise ConfigFileError(msg, error_no, self.log.name if self.log else "", context, self._url_base) \
mpf.exceptions.config_file_error.ConfigFileError: Config File Error in OPP: Chain 1 does not exist. Existing chains: ['COM7'] Error Code: CFE-OPP-3 (https://docs.missionpinball.org/en/0.55/logs/CFE-OPP-3.html)

The above exception was the direct cause of the following exception:

Traceback (most recent call last):
  File "C:\Users\dorus\AppData\Local\Programs\Python\Python38\lib\site-packages\mpf\core\system_wide_device.py", line 17, in device_added_system_wide
    await self._initialize()
  File "C:\Users\dorus\AppData\Local\Programs\Python\Python38\lib\site-packages\mpf\devices\switch.py", line 151, in _initialize
    raise ConfigFileError("Failed to configure switch {} in platform. See error above".format(self.name), 2,
mpf.exceptions.config_file_error.ConfigFileError: Config File Error in switch: Failed to configure switch s_left02 in platform. See error above Error Code: CFE-switch-2 (https://docs.missionpinball.org/en/0.55/logs/CFE-switch-2.html)
2022-10-16 17:09:22,254 : ERROR : asyncio : Task exception was never retrieved
future: <Task finished name='Task-64' coro=<SystemWideDevice.device_added_system_wide() done, defined at C:\Users\dorus\AppData\Local\Programs\Python\Python38\lib\site-packages\mpf\core\system_wide_device.py:15> exception=ConfigFileError('Failed to configure switch s_trough4 in platform. See error above')>
Traceback (most recent call last):
  File "C:\Users\dorus\AppData\Local\Programs\Python\Python38\lib\site-packages\mpf\devices\switch.py", line 148, in _initialize
    self.hw_switch = self.platform.configure_switch(
  File "C:\Users\dorus\AppData\Local\Programs\Python\Python38\lib\site-packages\mpf\platforms\opp\opp.py", line 825, in configure_switch
    number = self._get_dict_index(number)
  File "C:\Users\dorus\AppData\Local\Programs\Python\Python38\lib\site-packages\mpf\platforms\opp\opp.py", line 770, in _get_dict_index
    self.raise_config_error("Chain {} does not exist. Existing chains: {}".format(
  File "C:\Users\dorus\AppData\Local\Programs\Python\Python38\lib\site-packages\mpf\core\logging.py", line 172, in raise_config_error
    raise ConfigFileError(msg, error_no, self.log.name if self.log else "", context, self._url_base) \
mpf.exceptions.config_file_error.ConfigFileError: Config File Error in OPP: Chain 0 does not exist. Existing chains: ['COM7'] Error Code: CFE-OPP-3 (https://docs.missionpinball.org/en/0.55/logs/CFE-OPP-3.html)

The above exception was the direct cause of the following exception:

Traceback (most recent call last):
  File "C:\Users\dorus\AppData\Local\Programs\Python\Python38\lib\site-packages\mpf\core\system_wide_device.py", line 17, in device_added_system_wide
    await self._initialize()
  File "C:\Users\dorus\AppData\Local\Programs\Python\Python38\lib\site-packages\mpf\devices\switch.py", line 151, in _initialize
    raise ConfigFileError("Failed to configure switch {} in platform. See error above".format(self.name), 2,
mpf.exceptions.config_file_error.ConfigFileError: Config File Error in switch: Failed to configure switch s_trough4 in platform. See error above Error Code: CFE-switch-2 (https://docs.missionpinball.org/en/0.55/logs/CFE-switch-2.html)
2022-10-16 17:09:22,268 : ERROR : asyncio : Task exception was never retrieved
future: <Task finished name='Task-39' coro=<SystemWideDevice.device_added_system_wide() done, defined at C:\Users\dorus\AppData\Local\Programs\Python\Python38\lib\site-packages\mpf\core\system_wide_device.py:15> exception=ConfigFileError('Failed to configure switch s_toplane1 in platform. See error above')>
Traceback (most recent call last):
  File "C:\Users\dorus\AppData\Local\Programs\Python\Python38\lib\site-packages\mpf\devices\switch.py", line 148, in _initialize
    self.hw_switch = self.platform.configure_switch(
  File "C:\Users\dorus\AppData\Local\Programs\Python\Python38\lib\site-packages\mpf\platforms\opp\opp.py", line 825, in configure_switch
    number = self._get_dict_index(number)
  File "C:\Users\dorus\AppData\Local\Programs\Python\Python38\lib\site-packages\mpf\platforms\opp\opp.py", line 770, in _get_dict_index
    self.raise_config_error("Chain {} does not exist. Existing chains: {}".format(
  File "C:\Users\dorus\AppData\Local\Programs\Python\Python38\lib\site-packages\mpf\core\logging.py", line 172, in raise_config_error
    raise ConfigFileError(msg, error_no, self.log.name if self.log else "", context, self._url_base) \
mpf.exceptions.config_file_error.ConfigFileError: Config File Error in OPP: Chain 1 does not exist. Existing chains: ['COM7'] Error Code: CFE-OPP-3 (https://docs.missionpinball.org/en/0.55/logs/CFE-OPP-3.html)

The above exception was the direct cause of the following exception:

Traceback (most recent call last):
  File "C:\Users\dorus\AppData\Local\Programs\Python\Python38\lib\site-packages\mpf\core\system_wide_device.py", line 17, in device_added_system_wide
    await self._initialize()
  File "C:\Users\dorus\AppData\Local\Programs\Python\Python38\lib\site-packages\mpf\devices\switch.py", line 151, in _initialize
    raise ConfigFileError("Failed to configure switch {} in platform. See error above".format(self.name), 2,
mpf.exceptions.config_file_error.ConfigFileError: Config File Error in switch: Failed to configure switch s_toplane1 in platform. See error above Error Code: CFE-switch-2 (https://docs.missionpinball.org/en/0.55/logs/CFE-switch-2.html)
2022-10-16 17:09:22,268 : ERROR : asyncio : Task exception was never retrieved
future: <Task finished name='Task-14' coro=<SystemWideDevice.device_added_system_wide() done, defined at C:\Users\dorus\AppData\Local\Programs\Python\Python38\lib\site-packages\mpf\core\system_wide_device.py:15> exception=ConfigFileError('Failed to configure switch s_spinner in platform. See error above')>
Traceback (most recent call last):
  File "C:\Users\dorus\AppData\Local\Programs\Python\Python38\lib\site-packages\mpf\devices\switch.py", line 148, in _initialize
    self.hw_switch = self.platform.configure_switch(
  File "C:\Users\dorus\AppData\Local\Programs\Python\Python38\lib\site-packages\mpf\platforms\opp\opp.py", line 825, in configure_switch
    number = self._get_dict_index(number)
  File "C:\Users\dorus\AppData\Local\Programs\Python\Python38\lib\site-packages\mpf\platforms\opp\opp.py", line 770, in _get_dict_index
    self.raise_config_error("Chain {} does not exist. Existing chains: {}".format(
  File "C:\Users\dorus\AppData\Local\Programs\Python\Python38\lib\site-packages\mpf\core\logging.py", line 172, in raise_config_error
    raise ConfigFileError(msg, error_no, self.log.name if self.log else "", context, self._url_base) \
mpf.exceptions.config_file_error.ConfigFileError: Config File Error in OPP: Chain 1 does not exist. Existing chains: ['COM7'] Error Code: CFE-OPP-3 (https://docs.missionpinball.org/en/0.55/logs/CFE-OPP-3.html)

The above exception was the direct cause of the following exception:

Traceback (most recent call last):
  File "C:\Users\dorus\AppData\Local\Programs\Python\Python38\lib\site-packages\mpf\core\system_wide_device.py", line 17, in device_added_system_wide
    await self._initialize()
  File "C:\Users\dorus\AppData\Local\Programs\Python\Python38\lib\site-packages\mpf\devices\switch.py", line 151, in _initialize
    raise ConfigFileError("Failed to configure switch {} in platform. See error above".format(self.name), 2,
mpf.exceptions.config_file_error.ConfigFileError: Config File Error in switch: Failed to configure switch s_spinner in platform. See error above Error Code: CFE-switch-2 (https://docs.missionpinball.org/en/0.55/logs/CFE-switch-2.html)
2022-10-16 17:09:22,268 : ERROR : asyncio : Task exception was never retrieved
future: <Task finished name='Task-61' coro=<SystemWideDevice.device_added_system_wide() done, defined at C:\Users\dorus\AppData\Local\Programs\Python\Python38\lib\site-packages\mpf\core\system_wide_device.py:15> exception=ConfigFileError('Failed to configure switch s_bottomlane3 in platform. See error above')>
Traceback (most recent call last):
  File "C:\Users\dorus\AppData\Local\Programs\Python\Python38\lib\site-packages\mpf\devices\switch.py", line 148, in _initialize
    self.hw_switch = self.platform.configure_switch(
  File "C:\Users\dorus\AppData\Local\Programs\Python\Python38\lib\site-packages\mpf\platforms\opp\opp.py", line 825, in configure_switch
    number = self._get_dict_index(number)
  File "C:\Users\dorus\AppData\Local\Programs\Python\Python38\lib\site-packages\mpf\platforms\opp\opp.py", line 770, in _get_dict_index
    self.raise_config_error("Chain {} does not exist. Existing chains: {}".format(
  File "C:\Users\dorus\AppData\Local\Programs\Python\Python38\lib\site-packages\mpf\core\logging.py", line 172, in raise_config_error
    raise ConfigFileError(msg, error_no, self.log.name if self.log else "", context, self._url_base) \
mpf.exceptions.config_file_error.ConfigFileError: Config File Error in OPP: Chain 1 does not exist. Existing chains: ['COM7'] Error Code: CFE-OPP-3 (https://docs.missionpinball.org/en/0.55/logs/CFE-OPP-3.html)

The above exception was the direct cause of the following exception:

Traceback (most recent call last):
  File "C:\Users\dorus\AppData\Local\Programs\Python\Python38\lib\site-packages\mpf\core\system_wide_device.py", line 17, in device_added_system_wide
    await self._initialize()
  File "C:\Users\dorus\AppData\Local\Programs\Python\Python38\lib\site-packages\mpf\devices\switch.py", line 151, in _initialize
    raise ConfigFileError("Failed to configure switch {} in platform. See error above".format(self.name), 2,
mpf.exceptions.config_file_error.ConfigFileError: Config File Error in switch: Failed to configure switch s_bottomlane3 in platform. See error above Error Code: CFE-switch-2 (https://docs.missionpinball.org/en/0.55/logs/CFE-switch-2.html)
2022-10-16 17:09:22,268 : ERROR : asyncio : Task exception was never retrieved
future: <Task finished name='Task-27' coro=<SystemWideDevice.device_added_system_wide() done, defined at C:\Users\dorus\AppData\Local\Programs\Python\Python38\lib\site-packages\mpf\core\system_wide_device.py:15> exception=ConfigFileError('Failed to configure switch s_vuktop in platform. See error above')>
Traceback (most recent call last):
  File "C:\Users\dorus\AppData\Local\Programs\Python\Python38\lib\site-packages\mpf\devices\switch.py", line 148, in _initialize
    self.hw_switch = self.platform.configure_switch(
  File "C:\Users\dorus\AppData\Local\Programs\Python\Python38\lib\site-packages\mpf\platforms\opp\opp.py", line 825, in configure_switch
    number = self._get_dict_index(number)
  File "C:\Users\dorus\AppData\Local\Programs\Python\Python38\lib\site-packages\mpf\platforms\opp\opp.py", line 770, in _get_dict_index
    self.raise_config_error("Chain {} does not exist. Existing chains: {}".format(
  File "C:\Users\dorus\AppData\Local\Programs\Python\Python38\lib\site-packages\mpf\core\logging.py", line 172, in raise_config_error
    raise ConfigFileError(msg, error_no, self.log.name if self.log else "", context, self._url_base) \
mpf.exceptions.config_file_error.ConfigFileError: Config File Error in OPP: Chain 1 does not exist. Existing chains: ['COM7'] Error Code: CFE-OPP-3 (https://docs.missionpinball.org/en/0.55/logs/CFE-OPP-3.html)

The above exception was the direct cause of the following exception:

Traceback (most recent call last):
  File "C:\Users\dorus\AppData\Local\Programs\Python\Python38\lib\site-packages\mpf\core\system_wide_device.py", line 17, in device_added_system_wide
    await self._initialize()
  File "C:\Users\dorus\AppData\Local\Programs\Python\Python38\lib\site-packages\mpf\devices\switch.py", line 151, in _initialize
    raise ConfigFileError("Failed to configure switch {} in platform. See error above".format(self.name), 2,
mpf.exceptions.config_file_error.ConfigFileError: Config File Error in switch: Failed to configure switch s_vuktop in platform. See error above Error Code: CFE-switch-2 (https://docs.missionpinball.org/en/0.55/logs/CFE-switch-2.html)
2022-10-16 17:09:22,268 : ERROR : asyncio : Task exception was never retrieved
future: <Task finished name='Task-52' coro=<SystemWideDevice.device_added_system_wide() done, defined at C:\Users\dorus\AppData\Local\Programs\Python\Python38\lib\site-packages\mpf\core\system_wide_device.py:15> exception=ConfigFileError('Failed to configure switch s_trough1 in platform. See error above')>
Traceback (most recent call last):
  File "C:\Users\dorus\AppData\Local\Programs\Python\Python38\lib\site-packages\mpf\devices\switch.py", line 148, in _initialize
    self.hw_switch = self.platform.configure_switch(
  File "C:\Users\dorus\AppData\Local\Programs\Python\Python38\lib\site-packages\mpf\platforms\opp\opp.py", line 825, in configure_switch
    number = self._get_dict_index(number)
  File "C:\Users\dorus\AppData\Local\Programs\Python\Python38\lib\site-packages\mpf\platforms\opp\opp.py", line 770, in _get_dict_index
    self.raise_config_error("Chain {} does not exist. Existing chains: {}".format(
  File "C:\Users\dorus\AppData\Local\Programs\Python\Python38\lib\site-packages\mpf\core\logging.py", line 172, in raise_config_error
    raise ConfigFileError(msg, error_no, self.log.name if self.log else "", context, self._url_base) \
mpf.exceptions.config_file_error.ConfigFileError: Config File Error in OPP: Chain 1 does not exist. Existing chains: ['COM7'] Error Code: CFE-OPP-3 (https://docs.missionpinball.org/en/0.55/logs/CFE-OPP-3.html)

The above exception was the direct cause of the following exception:

Traceback (most recent call last):
  File "C:\Users\dorus\AppData\Local\Programs\Python\Python38\lib\site-packages\mpf\core\system_wide_device.py", line 17, in device_added_system_wide
    await self._initialize()
  File "C:\Users\dorus\AppData\Local\Programs\Python\Python38\lib\site-packages\mpf\devices\switch.py", line 151, in _initialize
    raise ConfigFileError("Failed to configure switch {} in platform. See error above".format(self.name), 2,
mpf.exceptions.config_file_error.ConfigFileError: Config File Error in switch: Failed to configure switch s_trough1 in platform. See error above Error Code: CFE-switch-2 (https://docs.missionpinball.org/en/0.55/logs/CFE-switch-2.html)
2022-10-16 17:09:22,268 : ERROR : asyncio : Task exception was never retrieved
future: <Task finished name='Task-15' coro=<SystemWideDevice.device_added_system_wide() done, defined at C:\Users\dorus\AppData\Local\Programs\Python\Python38\lib\site-packages\mpf\core\system_wide_device.py:15> exception=ConfigFileError('Failed to configure switch s_drop2 in platform. See error above')>
Traceback (most recent call last):
  File "C:\Users\dorus\AppData\Local\Programs\Python\Python38\lib\site-packages\mpf\devices\switch.py", line 148, in _initialize
    self.hw_switch = self.platform.configure_switch(
  File "C:\Users\dorus\AppData\Local\Programs\Python\Python38\lib\site-packages\mpf\platforms\opp\opp.py", line 825, in configure_switch
    number = self._get_dict_index(number)
  File "C:\Users\dorus\AppData\Local\Programs\Python\Python38\lib\site-packages\mpf\platforms\opp\opp.py", line 770, in _get_dict_index
    self.raise_config_error("Chain {} does not exist. Existing chains: {}".format(
  File "C:\Users\dorus\AppData\Local\Programs\Python\Python38\lib\site-packages\mpf\core\logging.py", line 172, in raise_config_error
    raise ConfigFileError(msg, error_no, self.log.name if self.log else "", context, self._url_base) \
mpf.exceptions.config_file_error.ConfigFileError: Config File Error in OPP: Chain 1 does not exist. Existing chains: ['COM7'] Error Code: CFE-OPP-3 (https://docs.missionpinball.org/en/0.55/logs/CFE-OPP-3.html)

The above exception was the direct cause of the following exception:

Traceback (most recent call last):
  File "C:\Users\dorus\AppData\Local\Programs\Python\Python38\lib\site-packages\mpf\core\system_wide_device.py", line 17, in device_added_system_wide
    await self._initialize()
  File "C:\Users\dorus\AppData\Local\Programs\Python\Python38\lib\site-packages\mpf\devices\switch.py", line 151, in _initialize
    raise ConfigFileError("Failed to configure switch {} in platform. See error above".format(self.name), 2,
mpf.exceptions.config_file_error.ConfigFileError: Config File Error in switch: Failed to configure switch s_drop2 in platform. See error above Error Code: CFE-switch-2 (https://docs.missionpinball.org/en/0.55/logs/CFE-switch-2.html)
2022-10-16 17:09:22,268 : ERROR : asyncio : Task exception was never retrieved
future: <Task finished name='Task-40' coro=<SystemWideDevice.device_added_system_wide() done, defined at C:\Users\dorus\AppData\Local\Programs\Python\Python38\lib\site-packages\mpf\core\system_wide_device.py:15> exception=AssertionError('Failed to configure light l3 in platform. See error above')>
Traceback (most recent call last):
  File "C:\Users\dorus\AppData\Local\Programs\Python\Python38\lib\site-packages\mpf\devices\light.py", line 284, in _load_hw_driver
    return platform.configure_light(channel['number'], channel['subtype'], config, channel['platform_settings'])
  File "C:\Users\dorus\AppData\Local\Programs\Python\Python38\lib\site-packages\mpf\platforms\opp\opp.py", line 871, in configure_light
    self.raise_config_error("A request was made to configure an OPP neopixel "
  File "C:\Users\dorus\AppData\Local\Programs\Python\Python38\lib\site-packages\mpf\core\logging.py", line 172, in raise_config_error
    raise ConfigFileError(msg, error_no, self.log.name if self.log else "", context, self._url_base) \
mpf.exceptions.config_file_error.ConfigFileError: Config File Error in OPP: A request was made to configure an OPP neopixel with card number 1 which doesn't exist Error Code: CFE-OPP-10 (https://docs.missionpinball.org/en/0.55/logs/CFE-OPP-10.html)

The above exception was the direct cause of the following exception:

Traceback (most recent call last):
  File "C:\Users\dorus\AppData\Local\Programs\Python\Python38\lib\site-packages\mpf\core\system_wide_device.py", line 17, in device_added_system_wide
    await self._initialize()
  File "C:\Users\dorus\AppData\Local\Programs\Python\Python38\lib\site-packages\mpf\devices\light.py", line 313, in _initialize
    self._load_hw_drivers()
  File "C:\Users\dorus\AppData\Local\Programs\Python\Python38\lib\site-packages\mpf\devices\light.py", line 267, in _load_hw_drivers
    driver = self._load_hw_driver(channel, color)
  File "C:\Users\dorus\AppData\Local\Programs\Python\Python38\lib\site-packages\mpf\devices\light.py", line 286, in _load_hw_driver
    raise AssertionError("Failed to configure light {} in platform. See error above".
AssertionError: Failed to configure light l3 in platform. See error above
2022-10-16 17:09:22,268 : ERROR : asyncio : Task exception was never retrieved
future: <Task finished name='Task-65' coro=<SystemWideDevice.device_added_system_wide() done, defined at C:\Users\dorus\AppData\Local\Programs\Python\Python38\lib\site-packages\mpf\core\system_wide_device.py:15> exception=ConfigFileError('Failed to configure switch s_bottomlane4 in platform. See error above')>
Traceback (most recent call last):
  File "C:\Users\dorus\AppData\Local\Programs\Python\Python38\lib\site-packages\mpf\devices\switch.py", line 148, in _initialize
    self.hw_switch = self.platform.configure_switch(
  File "C:\Users\dorus\AppData\Local\Programs\Python\Python38\lib\site-packages\mpf\platforms\opp\opp.py", line 825, in configure_switch
    number = self._get_dict_index(number)
  File "C:\Users\dorus\AppData\Local\Programs\Python\Python38\lib\site-packages\mpf\platforms\opp\opp.py", line 770, in _get_dict_index
    self.raise_config_error("Chain {} does not exist. Existing chains: {}".format(
  File "C:\Users\dorus\AppData\Local\Programs\Python\Python38\lib\site-packages\mpf\core\logging.py", line 172, in raise_config_error
    raise ConfigFileError(msg, error_no, self.log.name if self.log else "", context, self._url_base) \
mpf.exceptions.config_file_error.ConfigFileError: Config File Error in OPP: Chain 1 does not exist. Existing chains: ['COM7'] Error Code: CFE-OPP-3 (https://docs.missionpinball.org/en/0.55/logs/CFE-OPP-3.html)

The above exception was the direct cause of the following exception:

Traceback (most recent call last):
  File "C:\Users\dorus\AppData\Local\Programs\Python\Python38\lib\site-packages\mpf\core\system_wide_device.py", line 17, in device_added_system_wide
    await self._initialize()
  File "C:\Users\dorus\AppData\Local\Programs\Python\Python38\lib\site-packages\mpf\devices\switch.py", line 151, in _initialize
    raise ConfigFileError("Failed to configure switch {} in platform. See error above".format(self.name), 2,
mpf.exceptions.config_file_error.ConfigFileError: Config File Error in switch: Failed to configure switch s_bottomlane4 in platform. See error above Error Code: CFE-switch-2 (https://docs.missionpinball.org/en/0.55/logs/CFE-switch-2.html)
2022-10-16 17:09:22,268 : ERROR : asyncio : Task exception was never retrieved
future: <Task finished name='Task-53' coro=<SystemWideDevice.device_added_system_wide() done, defined at C:\Users\dorus\AppData\Local\Programs\Python\Python38\lib\site-packages\mpf\core\system_wide_device.py:15> exception=ConfigFileError('Failed to configure switch s_bottomlane1 in platform. See error above')>
Traceback (most recent call last):
  File "C:\Users\dorus\AppData\Local\Programs\Python\Python38\lib\site-packages\mpf\devices\switch.py", line 148, in _initialize
    self.hw_switch = self.platform.configure_switch(
  File "C:\Users\dorus\AppData\Local\Programs\Python\Python38\lib\site-packages\mpf\platforms\opp\opp.py", line 825, in configure_switch
    number = self._get_dict_index(number)
  File "C:\Users\dorus\AppData\Local\Programs\Python\Python38\lib\site-packages\mpf\platforms\opp\opp.py", line 770, in _get_dict_index
    self.raise_config_error("Chain {} does not exist. Existing chains: {}".format(
  File "C:\Users\dorus\AppData\Local\Programs\Python\Python38\lib\site-packages\mpf\core\logging.py", line 172, in raise_config_error
    raise ConfigFileError(msg, error_no, self.log.name if self.log else "", context, self._url_base) \
mpf.exceptions.config_file_error.ConfigFileError: Config File Error in OPP: Chain 1 does not exist. Existing chains: ['COM7'] Error Code: CFE-OPP-3 (https://docs.missionpinball.org/en/0.55/logs/CFE-OPP-3.html)

The above exception was the direct cause of the following exception:

Traceback (most recent call last):
  File "C:\Users\dorus\AppData\Local\Programs\Python\Python38\lib\site-packages\mpf\core\system_wide_device.py", line 17, in device_added_system_wide
    await self._initialize()
  File "C:\Users\dorus\AppData\Local\Programs\Python\Python38\lib\site-packages\mpf\devices\switch.py", line 151, in _initialize
    raise ConfigFileError("Failed to configure switch {} in platform. See error above".format(self.name), 2,
mpf.exceptions.config_file_error.ConfigFileError: Config File Error in switch: Failed to configure switch s_bottomlane1 in platform. See error above Error Code: CFE-switch-2 (https://docs.missionpinball.org/en/0.55/logs/CFE-switch-2.html)
2022-10-16 17:09:22,268 : ERROR : asyncio : Task exception was never retrieved
future: <Task finished name='Task-29' coro=<SystemWideDevice.device_added_system_wide() done, defined at C:\Users\dorus\AppData\Local\Programs\Python\Python38\lib\site-packages\mpf\core\system_wide_device.py:15> exception=ConfigFileError('Failed to configure switch s_popbumber_1 in platform. See error above')>
Traceback (most recent call last):
  File "C:\Users\dorus\AppData\Local\Programs\Python\Python38\lib\site-packages\mpf\devices\switch.py", line 148, in _initialize
    self.hw_switch = self.platform.configure_switch(
  File "C:\Users\dorus\AppData\Local\Programs\Python\Python38\lib\site-packages\mpf\platforms\opp\opp.py", line 825, in configure_switch
    number = self._get_dict_index(number)
  File "C:\Users\dorus\AppData\Local\Programs\Python\Python38\lib\site-packages\mpf\platforms\opp\opp.py", line 770, in _get_dict_index
    self.raise_config_error("Chain {} does not exist. Existing chains: {}".format(
  File "C:\Users\dorus\AppData\Local\Programs\Python\Python38\lib\site-packages\mpf\core\logging.py", line 172, in raise_config_error
    raise ConfigFileError(msg, error_no, self.log.name if self.log else "", context, self._url_base) \
mpf.exceptions.config_file_error.ConfigFileError: Config File Error in OPP: Chain 0 does not exist. Existing chains: ['COM7'] Error Code: CFE-OPP-3 (https://docs.missionpinball.org/en/0.55/logs/CFE-OPP-3.html)

The above exception was the direct cause of the following exception:

Traceback (most recent call last):
  File "C:\Users\dorus\AppData\Local\Programs\Python\Python38\lib\site-packages\mpf\core\system_wide_device.py", line 17, in device_added_system_wide
    await self._initialize()
  File "C:\Users\dorus\AppData\Local\Programs\Python\Python38\lib\site-packages\mpf\devices\switch.py", line 151, in _initialize
    raise ConfigFileError("Failed to configure switch {} in platform. See error above".format(self.name), 2,
mpf.exceptions.config_file_error.ConfigFileError: Config File Error in switch: Failed to configure switch s_popbumber_1 in platform. See error above Error Code: CFE-switch-2 (https://docs.missionpinball.org/en/0.55/logs/CFE-switch-2.html)
2022-10-16 17:09:22,268 : ERROR : asyncio : Task exception was never retrieved
future: <Task finished name='Task-17' coro=<SystemWideDevice.device_added_system_wide() done, defined at C:\Users\dorus\AppData\Local\Programs\Python\Python38\lib\site-packages\mpf\core\system_wide_device.py:15> exception=AssertionError('Failed to configure driver c_vuktop in platform. See error above')>
Traceback (most recent call last):
  File "C:\Users\dorus\AppData\Local\Programs\Python\Python38\lib\site-packages\mpf\devices\driver.py", line 107, in _initialize
    self.hw_driver = self.platform.configure_driver(config, self.config['number'], platform_settings)
  File "C:\Users\dorus\AppData\Local\Programs\Python\Python38\lib\site-packages\mpf\platforms\opp\opp.py", line 788, in configure_driver
    number = self._get_dict_index(number)
  File "C:\Users\dorus\AppData\Local\Programs\Python\Python38\lib\site-packages\mpf\platforms\opp\opp.py", line 770, in _get_dict_index
    self.raise_config_error("Chain {} does not exist. Existing chains: {}".format(
  File "C:\Users\dorus\AppData\Local\Programs\Python\Python38\lib\site-packages\mpf\core\logging.py", line 172, in raise_config_error
    raise ConfigFileError(msg, error_no, self.log.name if self.log else "", context, self._url_base) \
mpf.exceptions.config_file_error.ConfigFileError: Config File Error in OPP: Chain 1 does not exist. Existing chains: ['COM7'] Error Code: CFE-OPP-3 (https://docs.missionpinball.org/en/0.55/logs/CFE-OPP-3.html)

The above exception was the direct cause of the following exception:

Traceback (most recent call last):
  File "C:\Users\dorus\AppData\Local\Programs\Python\Python38\lib\site-packages\mpf\core\system_wide_device.py", line 17, in device_added_system_wide
    await self._initialize()
  File "C:\Users\dorus\AppData\Local\Programs\Python\Python38\lib\site-packages\mpf\devices\driver.py", line 109, in _initialize
    raise AssertionError("Failed to configure driver {} in platform. See error above".format(self.name)) from e
AssertionError: Failed to configure driver c_vuktop in platform. See error above
2022-10-16 17:09:22,268 : ERROR : asyncio : Task exception was never retrieved
future: <Task finished name='Task-42' coro=<SystemWideDevice.device_added_system_wide() done, defined at C:\Users\dorus\AppData\Local\Programs\Python\Python38\lib\site-packages\mpf\core\system_wide_device.py:15> exception=AssertionError('Failed to configure driver c_sling_left in platform. See error above')>
Traceback (most recent call last):
  File "C:\Users\dorus\AppData\Local\Programs\Python\Python38\lib\site-packages\mpf\devices\driver.py", line 107, in _initialize
    self.hw_driver = self.platform.configure_driver(config, self.config['number'], platform_settings)
  File "C:\Users\dorus\AppData\Local\Programs\Python\Python38\lib\site-packages\mpf\platforms\opp\opp.py", line 788, in configure_driver
    number = self._get_dict_index(number)
  File "C:\Users\dorus\AppData\Local\Programs\Python\Python38\lib\site-packages\mpf\platforms\opp\opp.py", line 770, in _get_dict_index
    self.raise_config_error("Chain {} does not exist. Existing chains: {}".format(
  File "C:\Users\dorus\AppData\Local\Programs\Python\Python38\lib\site-packages\mpf\core\logging.py", line 172, in raise_config_error
    raise ConfigFileError(msg, error_no, self.log.name if self.log else "", context, self._url_base) \
mpf.exceptions.config_file_error.ConfigFileError: Config File Error in OPP: Chain 0 does not exist. Existing chains: ['COM7'] Error Code: CFE-OPP-3 (https://docs.missionpinball.org/en/0.55/logs/CFE-OPP-3.html)

The above exception was the direct cause of the following exception:

Traceback (most recent call last):
  File "C:\Users\dorus\AppData\Local\Programs\Python\Python38\lib\site-packages\mpf\core\system_wide_device.py", line 17, in device_added_system_wide
    await self._initialize()
  File "C:\Users\dorus\AppData\Local\Programs\Python\Python38\lib\site-packages\mpf\devices\driver.py", line 109, in _initialize
    raise AssertionError("Failed to configure driver {} in platform. See error above".format(self.name)) from e
AssertionError: Failed to configure driver c_sling_left in platform. See error above
2022-10-16 17:09:22,268 : ERROR : asyncio : Task exception was never retrieved
future: <Task finished name='Task-67' coro=<SystemWideDevice.device_added_system_wide() done, defined at C:\Users\dorus\AppData\Local\Programs\Python\Python38\lib\site-packages\mpf\core\system_wide_device.py:15> exception=AssertionError('Failed to configure driver c_vukmid in platform. See error above')>
Traceback (most recent call last):
  File "C:\Users\dorus\AppData\Local\Programs\Python\Python38\lib\site-packages\mpf\devices\driver.py", line 107, in _initialize
    self.hw_driver = self.platform.configure_driver(config, self.config['number'], platform_settings)
  File "C:\Users\dorus\AppData\Local\Programs\Python\Python38\lib\site-packages\mpf\platforms\opp\opp.py", line 788, in configure_driver
    number = self._get_dict_index(number)
  File "C:\Users\dorus\AppData\Local\Programs\Python\Python38\lib\site-packages\mpf\platforms\opp\opp.py", line 770, in _get_dict_index
    self.raise_config_error("Chain {} does not exist. Existing chains: {}".format(
  File "C:\Users\dorus\AppData\Local\Programs\Python\Python38\lib\site-packages\mpf\core\logging.py", line 172, in raise_config_error
    raise ConfigFileError(msg, error_no, self.log.name if self.log else "", context, self._url_base) \
mpf.exceptions.config_file_error.ConfigFileError: Config File Error in OPP: Chain 1 does not exist. Existing chains: ['COM7'] Error Code: CFE-OPP-3 (https://docs.missionpinball.org/en/0.55/logs/CFE-OPP-3.html)

The above exception was the direct cause of the following exception:

Traceback (most recent call last):
  File "C:\Users\dorus\AppData\Local\Programs\Python\Python38\lib\site-packages\mpf\core\system_wide_device.py", line 17, in device_added_system_wide
    await self._initialize()
  File "C:\Users\dorus\AppData\Local\Programs\Python\Python38\lib\site-packages\mpf\devices\driver.py", line 109, in _initialize
    raise AssertionError("Failed to configure driver {} in platform. See error above".format(self.name)) from e
AssertionError: Failed to configure driver c_vukmid in platform. See error above
2022-10-16 17:09:22,268 : ERROR : asyncio : Task exception was never retrieved
future: <Task finished name='Task-30' coro=<SystemWideDevice.device_added_system_wide() done, defined at C:\Users\dorus\AppData\Local\Programs\Python\Python38\lib\site-packages\mpf\core\system_wide_device.py:15> exception=ConfigFileError('Failed to configure switch s_left03 in platform. See error above')>
Traceback (most recent call last):
  File "C:\Users\dorus\AppData\Local\Programs\Python\Python38\lib\site-packages\mpf\devices\switch.py", line 148, in _initialize
    self.hw_switch = self.platform.configure_switch(
  File "C:\Users\dorus\AppData\Local\Programs\Python\Python38\lib\site-packages\mpf\platforms\opp\opp.py", line 825, in configure_switch
    number = self._get_dict_index(number)
  File "C:\Users\dorus\AppData\Local\Programs\Python\Python38\lib\site-packages\mpf\platforms\opp\opp.py", line 770, in _get_dict_index
    self.raise_config_error("Chain {} does not exist. Existing chains: {}".format(
  File "C:\Users\dorus\AppData\Local\Programs\Python\Python38\lib\site-packages\mpf\core\logging.py", line 172, in raise_config_error
    raise ConfigFileError(msg, error_no, self.log.name if self.log else "", context, self._url_base) \
mpf.exceptions.config_file_error.ConfigFileError: Config File Error in OPP: Chain 1 does not exist. Existing chains: ['COM7'] Error Code: CFE-OPP-3 (https://docs.missionpinball.org/en/0.55/logs/CFE-OPP-3.html)

The above exception was the direct cause of the following exception:

Traceback (most recent call last):
  File "C:\Users\dorus\AppData\Local\Programs\Python\Python38\lib\site-packages\mpf\core\system_wide_device.py", line 17, in device_added_system_wide
    await self._initialize()
  File "C:\Users\dorus\AppData\Local\Programs\Python\Python38\lib\site-packages\mpf\devices\switch.py", line 151, in _initialize
    raise ConfigFileError("Failed to configure switch {} in platform. See error above".format(self.name), 2,
mpf.exceptions.config_file_error.ConfigFileError: Config File Error in switch: Failed to configure switch s_left03 in platform. See error above Error Code: CFE-switch-2 (https://docs.missionpinball.org/en/0.55/logs/CFE-switch-2.html)
2022-10-16 17:09:22,268 : ERROR : asyncio : Task exception was never retrieved
future: <Task finished name='Task-55' coro=<SystemWideDevice.device_added_system_wide() done, defined at C:\Users\dorus\AppData\Local\Programs\Python\Python38\lib\site-packages\mpf\core\system_wide_device.py:15> exception=AssertionError('Failed to configure driver c_popbumper_1 in platform. See error above')>
Traceback (most recent call last):
  File "C:\Users\dorus\AppData\Local\Programs\Python\Python38\lib\site-packages\mpf\devices\driver.py", line 107, in _initialize
    self.hw_driver = self.platform.configure_driver(config, self.config['number'], platform_settings)
  File "C:\Users\dorus\AppData\Local\Programs\Python\Python38\lib\site-packages\mpf\platforms\opp\opp.py", line 788, in configure_driver
    number = self._get_dict_index(number)
  File "C:\Users\dorus\AppData\Local\Programs\Python\Python38\lib\site-packages\mpf\platforms\opp\opp.py", line 770, in _get_dict_index
    self.raise_config_error("Chain {} does not exist. Existing chains: {}".format(
  File "C:\Users\dorus\AppData\Local\Programs\Python\Python38\lib\site-packages\mpf\core\logging.py", line 172, in raise_config_error
    raise ConfigFileError(msg, error_no, self.log.name if self.log else "", context, self._url_base) \
mpf.exceptions.config_file_error.ConfigFileError: Config File Error in OPP: Chain 0 does not exist. Existing chains: ['COM7'] Error Code: CFE-OPP-3 (https://docs.missionpinball.org/en/0.55/logs/CFE-OPP-3.html)

The above exception was the direct cause of the following exception:

Traceback (most recent call last):
  File "C:\Users\dorus\AppData\Local\Programs\Python\Python38\lib\site-packages\mpf\core\system_wide_device.py", line 17, in device_added_system_wide
    await self._initialize()
  File "C:\Users\dorus\AppData\Local\Programs\Python\Python38\lib\site-packages\mpf\devices\driver.py", line 109, in _initialize
    raise AssertionError("Failed to configure driver {} in platform. See error above".format(self.name)) from e
AssertionError: Failed to configure driver c_popbumper_1 in platform. See error above
2022-10-16 17:09:22,268 : ERROR : asyncio : Task exception was never retrieved
future: <Task finished name='Task-18' coro=<SystemWideDevice.device_added_system_wide() done, defined at C:\Users\dorus\AppData\Local\Programs\Python\Python38\lib\site-packages\mpf\core\system_wide_device.py:15> exception=ConfigFileError('Failed to configure switch s_ramp in platform. See error above')>
Traceback (most recent call last):
  File "C:\Users\dorus\AppData\Local\Programs\Python\Python38\lib\site-packages\mpf\devices\switch.py", line 148, in _initialize
    self.hw_switch = self.platform.configure_switch(
  File "C:\Users\dorus\AppData\Local\Programs\Python\Python38\lib\site-packages\mpf\platforms\opp\opp.py", line 825, in configure_switch
    number = self._get_dict_index(number)
  File "C:\Users\dorus\AppData\Local\Programs\Python\Python38\lib\site-packages\mpf\platforms\opp\opp.py", line 770, in _get_dict_index
    self.raise_config_error("Chain {} does not exist. Existing chains: {}".format(
  File "C:\Users\dorus\AppData\Local\Programs\Python\Python38\lib\site-packages\mpf\core\logging.py", line 172, in raise_config_error
    raise ConfigFileError(msg, error_no, self.log.name if self.log else "", context, self._url_base) \
mpf.exceptions.config_file_error.ConfigFileError: Config File Error in OPP: Chain 1 does not exist. Existing chains: ['COM7'] Error Code: CFE-OPP-3 (https://docs.missionpinball.org/en/0.55/logs/CFE-OPP-3.html)

The above exception was the direct cause of the following exception:

Traceback (most recent call last):
  File "C:\Users\dorus\AppData\Local\Programs\Python\Python38\lib\site-packages\mpf\core\system_wide_device.py", line 17, in device_added_system_wide
    await self._initialize()
  File "C:\Users\dorus\AppData\Local\Programs\Python\Python38\lib\site-packages\mpf\devices\switch.py", line 151, in _initialize
    raise ConfigFileError("Failed to configure switch {} in platform. See error above".format(self.name), 2,
mpf.exceptions.config_file_error.ConfigFileError: Config File Error in switch: Failed to configure switch s_ramp in platform. See error above Error Code: CFE-switch-2 (https://docs.missionpinball.org/en/0.55/logs/CFE-switch-2.html)
2022-10-16 17:09:22,268 : ERROR : asyncio : Task exception was never retrieved
future: <Task finished name='Task-43' coro=<SystemWideDevice.device_added_system_wide() done, defined at C:\Users\dorus\AppData\Local\Programs\Python\Python38\lib\site-packages\mpf\core\system_wide_device.py:15> exception=ConfigFileError('Failed to configure switch s_plunger_lane in platform. See error above')>
Traceback (most recent call last):
  File "C:\Users\dorus\AppData\Local\Programs\Python\Python38\lib\site-packages\mpf\devices\switch.py", line 148, in _initialize
    self.hw_switch = self.platform.configure_switch(
  File "C:\Users\dorus\AppData\Local\Programs\Python\Python38\lib\site-packages\mpf\platforms\opp\opp.py", line 825, in configure_switch
    number = self._get_dict_index(number)
  File "C:\Users\dorus\AppData\Local\Programs\Python\Python38\lib\site-packages\mpf\platforms\opp\opp.py", line 770, in _get_dict_index
    self.raise_config_error("Chain {} does not exist. Existing chains: {}".format(
  File "C:\Users\dorus\AppData\Local\Programs\Python\Python38\lib\site-packages\mpf\core\logging.py", line 172, in raise_config_error
    raise ConfigFileError(msg, error_no, self.log.name if self.log else "", context, self._url_base) \
mpf.exceptions.config_file_error.ConfigFileError: Config File Error in OPP: Chain 0 does not exist. Existing chains: ['COM7'] Error Code: CFE-OPP-3 (https://docs.missionpinball.org/en/0.55/logs/CFE-OPP-3.html)

The above exception was the direct cause of the following exception:

Traceback (most recent call last):
  File "C:\Users\dorus\AppData\Local\Programs\Python\Python38\lib\site-packages\mpf\core\system_wide_device.py", line 17, in device_added_system_wide
    await self._initialize()
  File "C:\Users\dorus\AppData\Local\Programs\Python\Python38\lib\site-packages\mpf\devices\switch.py", line 151, in _initialize
    raise ConfigFileError("Failed to configure switch {} in platform. See error above".format(self.name), 2,
mpf.exceptions.config_file_error.ConfigFileError: Config File Error in switch: Failed to configure switch s_plunger_lane in platform. See error above Error Code: CFE-switch-2 (https://docs.missionpinball.org/en/0.55/logs/CFE-switch-2.html)
2022-10-16 17:09:22,268 : ERROR : asyncio : Task exception was never retrieved
future: <Task finished name='Task-68' coro=<SystemWideDevice.device_added_system_wide() done, defined at C:\Users\dorus\AppData\Local\Programs\Python\Python38\lib\site-packages\mpf\core\system_wide_device.py:15> exception=ConfigFileError('Failed to configure switch s_trough5 in platform. See error above')>
Traceback (most recent call last):
  File "C:\Users\dorus\AppData\Local\Programs\Python\Python38\lib\site-packages\mpf\devices\switch.py", line 148, in _initialize
    self.hw_switch = self.platform.configure_switch(
  File "C:\Users\dorus\AppData\Local\Programs\Python\Python38\lib\site-packages\mpf\platforms\opp\opp.py", line 825, in configure_switch
    number = self._get_dict_index(number)
  File "C:\Users\dorus\AppData\Local\Programs\Python\Python38\lib\site-packages\mpf\platforms\opp\opp.py", line 770, in _get_dict_index
    self.raise_config_error("Chain {} does not exist. Existing chains: {}".format(
  File "C:\Users\dorus\AppData\Local\Programs\Python\Python38\lib\site-packages\mpf\core\logging.py", line 172, in raise_config_error
    raise ConfigFileError(msg, error_no, self.log.name if self.log else "", context, self._url_base) \
mpf.exceptions.config_file_error.ConfigFileError: Config File Error in OPP: Chain 1 does not exist. Existing chains: ['COM7'] Error Code: CFE-OPP-3 (https://docs.missionpinball.org/en/0.55/logs/CFE-OPP-3.html)

The above exception was the direct cause of the following exception:

Traceback (most recent call last):
  File "C:\Users\dorus\AppData\Local\Programs\Python\Python38\lib\site-packages\mpf\core\system_wide_device.py", line 17, in device_added_system_wide
    await self._initialize()
  File "C:\Users\dorus\AppData\Local\Programs\Python\Python38\lib\site-packages\mpf\devices\switch.py", line 151, in _initialize
    raise ConfigFileError("Failed to configure switch {} in platform. See error above".format(self.name), 2,
mpf.exceptions.config_file_error.ConfigFileError: Config File Error in switch: Failed to configure switch s_trough5 in platform. See error above Error Code: CFE-switch-2 (https://docs.missionpinball.org/en/0.55/logs/CFE-switch-2.html)
2022-10-16 17:09:22,284 : ERROR : asyncio : Task exception was never retrieved
future: <Task finished name='Task-31' coro=<SystemWideDevice.device_added_system_wide() done, defined at C:\Users\dorus\AppData\Local\Programs\Python\Python38\lib\site-packages\mpf\core\system_wide_device.py:15> exception=AssertionError('Failed to configure light L1 in platform. See error above')>
Traceback (most recent call last):
  File "C:\Users\dorus\AppData\Local\Programs\Python\Python38\lib\site-packages\mpf\devices\light.py", line 284, in _load_hw_driver
    return platform.configure_light(channel['number'], channel['subtype'], config, channel['platform_settings'])
  File "C:\Users\dorus\AppData\Local\Programs\Python\Python38\lib\site-packages\mpf\platforms\opp\opp.py", line 871, in configure_light
    self.raise_config_error("A request was made to configure an OPP neopixel "
  File "C:\Users\dorus\AppData\Local\Programs\Python\Python38\lib\site-packages\mpf\core\logging.py", line 172, in raise_config_error
    raise ConfigFileError(msg, error_no, self.log.name if self.log else "", context, self._url_base) \
mpf.exceptions.config_file_error.ConfigFileError: Config File Error in OPP: A request was made to configure an OPP neopixel with card number 1 which doesn't exist Error Code: CFE-OPP-10 (https://docs.missionpinball.org/en/0.55/logs/CFE-OPP-10.html)

The above exception was the direct cause of the following exception:

Traceback (most recent call last):
  File "C:\Users\dorus\AppData\Local\Programs\Python\Python38\lib\site-packages\mpf\core\system_wide_device.py", line 17, in device_added_system_wide
    await self._initialize()
  File "C:\Users\dorus\AppData\Local\Programs\Python\Python38\lib\site-packages\mpf\devices\light.py", line 313, in _initialize
    self._load_hw_drivers()
  File "C:\Users\dorus\AppData\Local\Programs\Python\Python38\lib\site-packages\mpf\devices\light.py", line 267, in _load_hw_drivers
    driver = self._load_hw_driver(channel, color)
  File "C:\Users\dorus\AppData\Local\Programs\Python\Python38\lib\site-packages\mpf\devices\light.py", line 286, in _load_hw_driver
    raise AssertionError("Failed to configure light {} in platform. See error above".
AssertionError: Failed to configure light L1 in platform. See error above
2022-10-16 17:09:22,284 : ERROR : asyncio : Task exception was never retrieved
future: <Task finished name='Task-56' coro=<SystemWideDevice.device_added_system_wide() done, defined at C:\Users\dorus\AppData\Local\Programs\Python\Python38\lib\site-packages\mpf\core\system_wide_device.py:15> exception=ConfigFileError('Failed to configure switch s_trough2 in platform. See error above')>
Traceback (most recent call last):
  File "C:\Users\dorus\AppData\Local\Programs\Python\Python38\lib\site-packages\mpf\devices\switch.py", line 148, in _initialize
    self.hw_switch = self.platform.configure_switch(
  File "C:\Users\dorus\AppData\Local\Programs\Python\Python38\lib\site-packages\mpf\platforms\opp\opp.py", line 825, in configure_switch
    number = self._get_dict_index(number)
  File "C:\Users\dorus\AppData\Local\Programs\Python\Python38\lib\site-packages\mpf\platforms\opp\opp.py", line 770, in _get_dict_index
    self.raise_config_error("Chain {} does not exist. Existing chains: {}".format(
  File "C:\Users\dorus\AppData\Local\Programs\Python\Python38\lib\site-packages\mpf\core\logging.py", line 172, in raise_config_error
    raise ConfigFileError(msg, error_no, self.log.name if self.log else "", context, self._url_base) \
mpf.exceptions.config_file_error.ConfigFileError: Config File Error in OPP: Chain 0 does not exist. Existing chains: ['COM7'] Error Code: CFE-OPP-3 (https://docs.missionpinball.org/en/0.55/logs/CFE-OPP-3.html)

The above exception was the direct cause of the following exception:

Traceback (most recent call last):
  File "C:\Users\dorus\AppData\Local\Programs\Python\Python38\lib\site-packages\mpf\core\system_wide_device.py", line 17, in device_added_system_wide
    await self._initialize()
  File "C:\Users\dorus\AppData\Local\Programs\Python\Python38\lib\site-packages\mpf\devices\switch.py", line 151, in _initialize
    raise ConfigFileError("Failed to configure switch {} in platform. See error above".format(self.name), 2,
mpf.exceptions.config_file_error.ConfigFileError: Config File Error in switch: Failed to configure switch s_trough2 in platform. See error above Error Code: CFE-switch-2 (https://docs.missionpinball.org/en/0.55/logs/CFE-switch-2.html)
2022-10-16 17:09:22,284 : ERROR : asyncio : Task exception was never retrieved
future: <Task finished name='Task-19' coro=<SystemWideDevice.device_added_system_wide() done, defined at C:\Users\dorus\AppData\Local\Programs\Python\Python38\lib\site-packages\mpf\core\system_wide_device.py:15> exception=ConfigFileError('Failed to configure switch s_drop3 in platform. See error above')>
Traceback (most recent call last):
  File "C:\Users\dorus\AppData\Local\Programs\Python\Python38\lib\site-packages\mpf\devices\switch.py", line 148, in _initialize
    self.hw_switch = self.platform.configure_switch(
  File "C:\Users\dorus\AppData\Local\Programs\Python\Python38\lib\site-packages\mpf\platforms\opp\opp.py", line 825, in configure_switch
    number = self._get_dict_index(number)
  File "C:\Users\dorus\AppData\Local\Programs\Python\Python38\lib\site-packages\mpf\platforms\opp\opp.py", line 770, in _get_dict_index
    self.raise_config_error("Chain {} does not exist. Existing chains: {}".format(
  File "C:\Users\dorus\AppData\Local\Programs\Python\Python38\lib\site-packages\mpf\core\logging.py", line 172, in raise_config_error
    raise ConfigFileError(msg, error_no, self.log.name if self.log else "", context, self._url_base) \
mpf.exceptions.config_file_error.ConfigFileError: Config File Error in OPP: Chain 1 does not exist. Existing chains: ['COM7'] Error Code: CFE-OPP-3 (https://docs.missionpinball.org/en/0.55/logs/CFE-OPP-3.html)

The above exception was the direct cause of the following exception:

Traceback (most recent call last):
  File "C:\Users\dorus\AppData\Local\Programs\Python\Python38\lib\site-packages\mpf\core\system_wide_device.py", line 17, in device_added_system_wide
    await self._initialize()
  File "C:\Users\dorus\AppData\Local\Programs\Python\Python38\lib\site-packages\mpf\devices\switch.py", line 151, in _initialize
    raise ConfigFileError("Failed to configure switch {} in platform. See error above".format(self.name), 2,
mpf.exceptions.config_file_error.ConfigFileError: Config File Error in switch: Failed to configure switch s_drop3 in platform. See error above Error Code: CFE-switch-2 (https://docs.missionpinball.org/en/0.55/logs/CFE-switch-2.html)
2022-10-16 17:09:22,284 : ERROR : asyncio : Task exception was never retrieved
future: <Task finished name='Task-44' coro=<SystemWideDevice.device_added_system_wide() done, defined at C:\Users\dorus\AppData\Local\Programs\Python\Python38\lib\site-packages\mpf\core\system_wide_device.py:15> exception=ConfigFileError('Failed to configure switch s_toplane2 in platform. See error above')>
Traceback (most recent call last):
  File "C:\Users\dorus\AppData\Local\Programs\Python\Python38\lib\site-packages\mpf\devices\switch.py", line 148, in _initialize
    self.hw_switch = self.platform.configure_switch(
  File "C:\Users\dorus\AppData\Local\Programs\Python\Python38\lib\site-packages\mpf\platforms\opp\opp.py", line 825, in configure_switch
    number = self._get_dict_index(number)
  File "C:\Users\dorus\AppData\Local\Programs\Python\Python38\lib\site-packages\mpf\platforms\opp\opp.py", line 770, in _get_dict_index
    self.raise_config_error("Chain {} does not exist. Existing chains: {}".format(
  File "C:\Users\dorus\AppData\Local\Programs\Python\Python38\lib\site-packages\mpf\core\logging.py", line 172, in raise_config_error
    raise ConfigFileError(msg, error_no, self.log.name if self.log else "", context, self._url_base) \
mpf.exceptions.config_file_error.ConfigFileError: Config File Error in OPP: Chain 1 does not exist. Existing chains: ['COM7'] Error Code: CFE-OPP-3 (https://docs.missionpinball.org/en/0.55/logs/CFE-OPP-3.html)

The above exception was the direct cause of the following exception:

Traceback (most recent call last):
  File "C:\Users\dorus\AppData\Local\Programs\Python\Python38\lib\site-packages\mpf\core\system_wide_device.py", line 17, in device_added_system_wide
    await self._initialize()
  File "C:\Users\dorus\AppData\Local\Programs\Python\Python38\lib\site-packages\mpf\devices\switch.py", line 151, in _initialize
    raise ConfigFileError("Failed to configure switch {} in platform. See error above".format(self.name), 2,
mpf.exceptions.config_file_error.ConfigFileError: Config File Error in switch: Failed to configure switch s_toplane2 in platform. See error above Error Code: CFE-switch-2 (https://docs.missionpinball.org/en/0.55/logs/CFE-switch-2.html)
2022-10-16 17:09:22,284 : ERROR : asyncio : Task exception was never retrieved
future: <Task finished name='Task-69' coro=<SystemWideDevice.device_added_system_wide() done, defined at C:\Users\dorus\AppData\Local\Programs\Python\Python38\lib\site-packages\mpf\core\system_wide_device.py:15> exception=ConfigFileError('Failed to configure switch s_bottomlane5 in platform. See error above')>
Traceback (most recent call last):
  File "C:\Users\dorus\AppData\Local\Programs\Python\Python38\lib\site-packages\mpf\devices\switch.py", line 148, in _initialize
    self.hw_switch = self.platform.configure_switch(
  File "C:\Users\dorus\AppData\Local\Programs\Python\Python38\lib\site-packages\mpf\platforms\opp\opp.py", line 825, in configure_switch
    number = self._get_dict_index(number)
  File "C:\Users\dorus\AppData\Local\Programs\Python\Python38\lib\site-packages\mpf\platforms\opp\opp.py", line 770, in _get_dict_index
    self.raise_config_error("Chain {} does not exist. Existing chains: {}".format(
  File "C:\Users\dorus\AppData\Local\Programs\Python\Python38\lib\site-packages\mpf\core\logging.py", line 172, in raise_config_error
    raise ConfigFileError(msg, error_no, self.log.name if self.log else "", context, self._url_base) \
mpf.exceptions.config_file_error.ConfigFileError: Config File Error in OPP: Chain 1 does not exist. Existing chains: ['COM7'] Error Code: CFE-OPP-3 (https://docs.missionpinball.org/en/0.55/logs/CFE-OPP-3.html)

The above exception was the direct cause of the following exception:

Traceback (most recent call last):
  File "C:\Users\dorus\AppData\Local\Programs\Python\Python38\lib\site-packages\mpf\core\system_wide_device.py", line 17, in device_added_system_wide
    await self._initialize()
  File "C:\Users\dorus\AppData\Local\Programs\Python\Python38\lib\site-packages\mpf\devices\switch.py", line 151, in _initialize
    raise ConfigFileError("Failed to configure switch {} in platform. See error above".format(self.name), 2,
mpf.exceptions.config_file_error.ConfigFileError: Config File Error in switch: Failed to configure switch s_bottomlane5 in platform. See error above Error Code: CFE-switch-2 (https://docs.missionpinball.org/en/0.55/logs/CFE-switch-2.html)
2022-10-16 17:09:22,284 : ERROR : asyncio : Task exception was never retrieved
future: <Task finished name='Task-57' coro=<SystemWideDevice.device_added_system_wide() done, defined at C:\Users\dorus\AppData\Local\Programs\Python\Python38\lib\site-packages\mpf\core\system_wide_device.py:15> exception=ConfigFileError('Failed to configure switch s_bottomlane2 in platform. See error above')>
Traceback (most recent call last):
  File "C:\Users\dorus\AppData\Local\Programs\Python\Python38\lib\site-packages\mpf\devices\switch.py", line 148, in _initialize
    self.hw_switch = self.platform.configure_switch(
  File "C:\Users\dorus\AppData\Local\Programs\Python\Python38\lib\site-packages\mpf\platforms\opp\opp.py", line 825, in configure_switch
    number = self._get_dict_index(number)
  File "C:\Users\dorus\AppData\Local\Programs\Python\Python38\lib\site-packages\mpf\platforms\opp\opp.py", line 770, in _get_dict_index
    self.raise_config_error("Chain {} does not exist. Existing chains: {}".format(
  File "C:\Users\dorus\AppData\Local\Programs\Python\Python38\lib\site-packages\mpf\core\logging.py", line 172, in raise_config_error
    raise ConfigFileError(msg, error_no, self.log.name if self.log else "", context, self._url_base) \
mpf.exceptions.config_file_error.ConfigFileError: Config File Error in OPP: Chain 1 does not exist. Existing chains: ['COM7'] Error Code: CFE-OPP-3 (https://docs.missionpinball.org/en/0.55/logs/CFE-OPP-3.html)

The above exception was the direct cause of the following exception:

Traceback (most recent call last):
  File "C:\Users\dorus\AppData\Local\Programs\Python\Python38\lib\site-packages\mpf\core\system_wide_device.py", line 17, in device_added_system_wide
    await self._initialize()
  File "C:\Users\dorus\AppData\Local\Programs\Python\Python38\lib\site-packages\mpf\devices\switch.py", line 151, in _initialize
    raise ConfigFileError("Failed to configure switch {} in platform. See error above".format(self.name), 2,
mpf.exceptions.config_file_error.ConfigFileError: Config File Error in switch: Failed to configure switch s_bottomlane2 in platform. See error above Error Code: CFE-switch-2 (https://docs.missionpinball.org/en/0.55/logs/CFE-switch-2.html)
2022-10-16 17:09:22,284 : ERROR : asyncio : Task exception was never retrieved
future: <Task finished name='Task-33' coro=<SystemWideDevice.device_added_system_wide() done, defined at C:\Users\dorus\AppData\Local\Programs\Python\Python38\lib\site-packages\mpf\core\system_wide_device.py:15> exception=ConfigFileError('Failed to configure switch s_popbumber_2 in platform. See error above')>
Traceback (most recent call last):
  File "C:\Users\dorus\AppData\Local\Programs\Python\Python38\lib\site-packages\mpf\devices\switch.py", line 148, in _initialize
    self.hw_switch = self.platform.configure_switch(
  File "C:\Users\dorus\AppData\Local\Programs\Python\Python38\lib\site-packages\mpf\platforms\opp\opp.py", line 825, in configure_switch
    number = self._get_dict_index(number)
  File "C:\Users\dorus\AppData\Local\Programs\Python\Python38\lib\site-packages\mpf\platforms\opp\opp.py", line 770, in _get_dict_index
    self.raise_config_error("Chain {} does not exist. Existing chains: {}".format(
  File "C:\Users\dorus\AppData\Local\Programs\Python\Python38\lib\site-packages\mpf\core\logging.py", line 172, in raise_config_error
    raise ConfigFileError(msg, error_no, self.log.name if self.log else "", context, self._url_base) \
mpf.exceptions.config_file_error.ConfigFileError: Config File Error in OPP: Chain 0 does not exist. Existing chains: ['COM7'] Error Code: CFE-OPP-3 (https://docs.missionpinball.org/en/0.55/logs/CFE-OPP-3.html)

The above exception was the direct cause of the following exception:

Traceback (most recent call last):
  File "C:\Users\dorus\AppData\Local\Programs\Python\Python38\lib\site-packages\mpf\core\system_wide_device.py", line 17, in device_added_system_wide
    await self._initialize()
  File "C:\Users\dorus\AppData\Local\Programs\Python\Python38\lib\site-packages\mpf\devices\switch.py", line 151, in _initialize
    raise ConfigFileError("Failed to configure switch {} in platform. See error above".format(self.name), 2,
mpf.exceptions.config_file_error.ConfigFileError: Config File Error in switch: Failed to configure switch s_popbumber_2 in platform. See error above Error Code: CFE-switch-2 (https://docs.missionpinball.org/en/0.55/logs/CFE-switch-2.html)
2022-10-16 17:09:22,284 : ERROR : asyncio : Task exception was never retrieved
future: <Task finished name='Task-21' coro=<SystemWideDevice.device_added_system_wide() done, defined at C:\Users\dorus\AppData\Local\Programs\Python\Python38\lib\site-packages\mpf\core\system_wide_device.py:15> exception=ConfigFileError('Failed to configure switch s_right_sling in platform. See error above')>
Traceback (most recent call last):
  File "C:\Users\dorus\AppData\Local\Programs\Python\Python38\lib\site-packages\mpf\devices\switch.py", line 148, in _initialize
    self.hw_switch = self.platform.configure_switch(
  File "C:\Users\dorus\AppData\Local\Programs\Python\Python38\lib\site-packages\mpf\platforms\opp\opp.py", line 825, in configure_switch
    number = self._get_dict_index(number)
  File "C:\Users\dorus\AppData\Local\Programs\Python\Python38\lib\site-packages\mpf\platforms\opp\opp.py", line 770, in _get_dict_index
    self.raise_config_error("Chain {} does not exist. Existing chains: {}".format(
  File "C:\Users\dorus\AppData\Local\Programs\Python\Python38\lib\site-packages\mpf\core\logging.py", line 172, in raise_config_error
    raise ConfigFileError(msg, error_no, self.log.name if self.log else "", context, self._url_base) \
mpf.exceptions.config_file_error.ConfigFileError: Config File Error in OPP: Chain 0 does not exist. Existing chains: ['COM7'] Error Code: CFE-OPP-3 (https://docs.missionpinball.org/en/0.55/logs/CFE-OPP-3.html)

The above exception was the direct cause of the following exception:

Traceback (most recent call last):
  File "C:\Users\dorus\AppData\Local\Programs\Python\Python38\lib\site-packages\mpf\core\system_wide_device.py", line 17, in device_added_system_wide
    await self._initialize()
  File "C:\Users\dorus\AppData\Local\Programs\Python\Python38\lib\site-packages\mpf\devices\switch.py", line 151, in _initialize
    raise ConfigFileError("Failed to configure switch {} in platform. See error above".format(self.name), 2,
mpf.exceptions.config_file_error.ConfigFileError: Config File Error in switch: Failed to configure switch s_right_sling in platform. See error above Error Code: CFE-switch-2 (https://docs.missionpinball.org/en/0.55/logs/CFE-switch-2.html)
2022-10-16 17:09:22,284 : ERROR : asyncio : Task exception was never retrieved
future: <Task finished name='Task-71' coro=<SystemWideDevice.device_added_system_wide() done, defined at C:\Users\dorus\AppData\Local\Programs\Python\Python38\lib\site-packages\mpf\core\system_wide_device.py:15> exception=ConfigFileError('Failed to configure switch s_trough6 in platform. See error above')>
Traceback (most recent call last):
  File "C:\Users\dorus\AppData\Local\Programs\Python\Python38\lib\site-packages\mpf\devices\switch.py", line 148, in _initialize
    self.hw_switch = self.platform.configure_switch(
  File "C:\Users\dorus\AppData\Local\Programs\Python\Python38\lib\site-packages\mpf\platforms\opp\opp.py", line 825, in configure_switch
    number = self._get_dict_index(number)
  File "C:\Users\dorus\AppData\Local\Programs\Python\Python38\lib\site-packages\mpf\platforms\opp\opp.py", line 770, in _get_dict_index
    self.raise_config_error("Chain {} does not exist. Existing chains: {}".format(
  File "C:\Users\dorus\AppData\Local\Programs\Python\Python38\lib\site-packages\mpf\core\logging.py", line 172, in raise_config_error
    raise ConfigFileError(msg, error_no, self.log.name if self.log else "", context, self._url_base) \
mpf.exceptions.config_file_error.ConfigFileError: Config File Error in OPP: Chain 1 does not exist. Existing chains: ['COM7'] Error Code: CFE-OPP-3 (https://docs.missionpinball.org/en/0.55/logs/CFE-OPP-3.html)

The above exception was the direct cause of the following exception:

Traceback (most recent call last):
  File "C:\Users\dorus\AppData\Local\Programs\Python\Python38\lib\site-packages\mpf\core\system_wide_device.py", line 17, in device_added_system_wide
    await self._initialize()
  File "C:\Users\dorus\AppData\Local\Programs\Python\Python38\lib\site-packages\mpf\devices\switch.py", line 151, in _initialize
    raise ConfigFileError("Failed to configure switch {} in platform. See error above".format(self.name), 2,
mpf.exceptions.config_file_error.ConfigFileError: Config File Error in switch: Failed to configure switch s_trough6 in platform. See error above Error Code: CFE-switch-2 (https://docs.missionpinball.org/en/0.55/logs/CFE-switch-2.html)
2022-10-16 17:09:22,284 : ERROR : asyncio : Task exception was never retrieved
future: <Task finished name='Task-9' coro=<SystemWideDevice.device_added_system_wide() done, defined at C:\Users\dorus\AppData\Local\Programs\Python\Python38\lib\site-packages\mpf\core\system_wide_device.py:15> exception=AssertionError('Failed to configure driver c_drop in platform. See error above')>
Traceback (most recent call last):
  File "C:\Users\dorus\AppData\Local\Programs\Python\Python38\lib\site-packages\mpf\devices\driver.py", line 107, in _initialize
    self.hw_driver = self.platform.configure_driver(config, self.config['number'], platform_settings)
  File "C:\Users\dorus\AppData\Local\Programs\Python\Python38\lib\site-packages\mpf\platforms\opp\opp.py", line 788, in configure_driver
    number = self._get_dict_index(number)
  File "C:\Users\dorus\AppData\Local\Programs\Python\Python38\lib\site-packages\mpf\platforms\opp\opp.py", line 770, in _get_dict_index
    self.raise_config_error("Chain {} does not exist. Existing chains: {}".format(
  File "C:\Users\dorus\AppData\Local\Programs\Python\Python38\lib\site-packages\mpf\core\logging.py", line 172, in raise_config_error
    raise ConfigFileError(msg, error_no, self.log.name if self.log else "", context, self._url_base) \
mpf.exceptions.config_file_error.ConfigFileError: Config File Error in OPP: Chain 1 does not exist. Existing chains: ['COM7'] Error Code: CFE-OPP-3 (https://docs.missionpinball.org/en/0.55/logs/CFE-OPP-3.html)

The above exception was the direct cause of the following exception:

Traceback (most recent call last):
  File "C:\Users\dorus\AppData\Local\Programs\Python\Python38\lib\site-packages\mpf\core\system_wide_device.py", line 17, in device_added_system_wide
    await self._initialize()
  File "C:\Users\dorus\AppData\Local\Programs\Python\Python38\lib\site-packages\mpf\devices\driver.py", line 109, in _initialize
    raise AssertionError("Failed to configure driver {} in platform. See error above".format(self.name)) from e
AssertionError: Failed to configure driver c_drop in platform. See error above
2022-10-16 17:09:22,284 : ERROR : asyncio : Task exception was never retrieved
future: <Task finished name='Task-34' coro=<SystemWideDevice.device_added_system_wide() done, defined at C:\Users\dorus\AppData\Local\Programs\Python\Python38\lib\site-packages\mpf\core\system_wide_device.py:15> exception=ConfigFileError('Failed to configure switch s_top in platform. See error above')>
Traceback (most recent call last):
  File "C:\Users\dorus\AppData\Local\Programs\Python\Python38\lib\site-packages\mpf\devices\switch.py", line 148, in _initialize
    self.hw_switch = self.platform.configure_switch(
  File "C:\Users\dorus\AppData\Local\Programs\Python\Python38\lib\site-packages\mpf\platforms\opp\opp.py", line 825, in configure_switch
    number = self._get_dict_index(number)
  File "C:\Users\dorus\AppData\Local\Programs\Python\Python38\lib\site-packages\mpf\platforms\opp\opp.py", line 770, in _get_dict_index
    self.raise_config_error("Chain {} does not exist. Existing chains: {}".format(
  File "C:\Users\dorus\AppData\Local\Programs\Python\Python38\lib\site-packages\mpf\core\logging.py", line 172, in raise_config_error
    raise ConfigFileError(msg, error_no, self.log.name if self.log else "", context, self._url_base) \
mpf.exceptions.config_file_error.ConfigFileError: Config File Error in OPP: Chain 1 does not exist. Existing chains: ['COM7'] Error Code: CFE-OPP-3 (https://docs.missionpinball.org/en/0.55/logs/CFE-OPP-3.html)

The above exception was the direct cause of the following exception:

Traceback (most recent call last):
  File "C:\Users\dorus\AppData\Local\Programs\Python\Python38\lib\site-packages\mpf\core\system_wide_device.py", line 17, in device_added_system_wide
    await self._initialize()
  File "C:\Users\dorus\AppData\Local\Programs\Python\Python38\lib\site-packages\mpf\devices\switch.py", line 151, in _initialize
    raise ConfigFileError("Failed to configure switch {} in platform. See error above".format(self.name), 2,
mpf.exceptions.config_file_error.ConfigFileError: Config File Error in switch: Failed to configure switch s_top in platform. See error above Error Code: CFE-switch-2 (https://docs.missionpinball.org/en/0.55/logs/CFE-switch-2.html)
2022-10-16 17:09:22,284 : ERROR : asyncio : Task exception was never retrieved
future: <Task finished name='Task-22' coro=<SystemWideDevice.device_added_system_wide() done, defined at C:\Users\dorus\AppData\Local\Programs\Python\Python38\lib\site-packages\mpf\core\system_wide_device.py:15> exception=ConfigFileError('Failed to configure switch s_left01 in platform. See error above')>
Traceback (most recent call last):
  File "C:\Users\dorus\AppData\Local\Programs\Python\Python38\lib\site-packages\mpf\devices\switch.py", line 148, in _initialize
    self.hw_switch = self.platform.configure_switch(
  File "C:\Users\dorus\AppData\Local\Programs\Python\Python38\lib\site-packages\mpf\platforms\opp\opp.py", line 825, in configure_switch
    number = self._get_dict_index(number)
  File "C:\Users\dorus\AppData\Local\Programs\Python\Python38\lib\site-packages\mpf\platforms\opp\opp.py", line 770, in _get_dict_index
    self.raise_config_error("Chain {} does not exist. Existing chains: {}".format(
  File "C:\Users\dorus\AppData\Local\Programs\Python\Python38\lib\site-packages\mpf\core\logging.py", line 172, in raise_config_error
    raise ConfigFileError(msg, error_no, self.log.name if self.log else "", context, self._url_base) \
mpf.exceptions.config_file_error.ConfigFileError: Config File Error in OPP: Chain 1 does not exist. Existing chains: ['COM7'] Error Code: CFE-OPP-3 (https://docs.missionpinball.org/en/0.55/logs/CFE-OPP-3.html)

The above exception was the direct cause of the following exception:

Traceback (most recent call last):
  File "C:\Users\dorus\AppData\Local\Programs\Python\Python38\lib\site-packages\mpf\core\system_wide_device.py", line 17, in device_added_system_wide
    await self._initialize()
  File "C:\Users\dorus\AppData\Local\Programs\Python\Python38\lib\site-packages\mpf\devices\switch.py", line 151, in _initialize
    raise ConfigFileError("Failed to configure switch {} in platform. See error above".format(self.name), 2,
mpf.exceptions.config_file_error.ConfigFileError: Config File Error in switch: Failed to configure switch s_left01 in platform. See error above Error Code: CFE-switch-2 (https://docs.missionpinball.org/en/0.55/logs/CFE-switch-2.html)
2022-10-16 17:09:22,284 : ERROR : asyncio : Task exception was never retrieved
future: <Task finished name='Task-47' coro=<SystemWideDevice.device_added_system_wide() done, defined at C:\Users\dorus\AppData\Local\Programs\Python\Python38\lib\site-packages\mpf\core\system_wide_device.py:15> exception=AssertionError('Failed to configure driver c_plunger in platform. See error above')>
Traceback (most recent call last):
  File "C:\Users\dorus\AppData\Local\Programs\Python\Python38\lib\site-packages\mpf\devices\driver.py", line 107, in _initialize
    self.hw_driver = self.platform.configure_driver(config, self.config['number'], platform_settings)
  File "C:\Users\dorus\AppData\Local\Programs\Python\Python38\lib\site-packages\mpf\platforms\opp\opp.py", line 788, in configure_driver
    number = self._get_dict_index(number)
  File "C:\Users\dorus\AppData\Local\Programs\Python\Python38\lib\site-packages\mpf\platforms\opp\opp.py", line 770, in _get_dict_index
    self.raise_config_error("Chain {} does not exist. Existing chains: {}".format(
  File "C:\Users\dorus\AppData\Local\Programs\Python\Python38\lib\site-packages\mpf\core\logging.py", line 172, in raise_config_error
    raise ConfigFileError(msg, error_no, self.log.name if self.log else "", context, self._url_base) \
mpf.exceptions.config_file_error.ConfigFileError: Config File Error in OPP: Chain 0 does not exist. Existing chains: ['COM7'] Error Code: CFE-OPP-3 (https://docs.missionpinball.org/en/0.55/logs/CFE-OPP-3.html)

The above exception was the direct cause of the following exception:

Traceback (most recent call last):
  File "C:\Users\dorus\AppData\Local\Programs\Python\Python38\lib\site-packages\mpf\core\system_wide_device.py", line 17, in device_added_system_wide
    await self._initialize()
  File "C:\Users\dorus\AppData\Local\Programs\Python\Python38\lib\site-packages\mpf\devices\driver.py", line 109, in _initialize
    raise AssertionError("Failed to configure driver {} in platform. See error above".format(self.name)) from e
AssertionError: Failed to configure driver c_plunger in platform. See error above
2022-10-16 17:09:22,284 : ERROR : asyncio : Task exception was never retrieved
future: <Task finished name='Task-59' coro=<SystemWideDevice.device_added_system_wide() done, defined at C:\Users\dorus\AppData\Local\Programs\Python\Python38\lib\site-packages\mpf\core\system_wide_device.py:15> exception=AssertionError('Failed to configure driver c_popbumper_2 in platform. See error above')>
Traceback (most recent call last):
  File "C:\Users\dorus\AppData\Local\Programs\Python\Python38\lib\site-packages\mpf\devices\driver.py", line 107, in _initialize
    self.hw_driver = self.platform.configure_driver(config, self.config['number'], platform_settings)
  File "C:\Users\dorus\AppData\Local\Programs\Python\Python38\lib\site-packages\mpf\platforms\opp\opp.py", line 788, in configure_driver
    number = self._get_dict_index(number)
  File "C:\Users\dorus\AppData\Local\Programs\Python\Python38\lib\site-packages\mpf\platforms\opp\opp.py", line 770, in _get_dict_index
    self.raise_config_error("Chain {} does not exist. Existing chains: {}".format(
  File "C:\Users\dorus\AppData\Local\Programs\Python\Python38\lib\site-packages\mpf\core\logging.py", line 172, in raise_config_error
    raise ConfigFileError(msg, error_no, self.log.name if self.log else "", context, self._url_base) \
mpf.exceptions.config_file_error.ConfigFileError: Config File Error in OPP: Chain 0 does not exist. Existing chains: ['COM7'] Error Code: CFE-OPP-3 (https://docs.missionpinball.org/en/0.55/logs/CFE-OPP-3.html)

The above exception was the direct cause of the following exception:

Traceback (most recent call last):
  File "C:\Users\dorus\AppData\Local\Programs\Python\Python38\lib\site-packages\mpf\core\system_wide_device.py", line 17, in device_added_system_wide
    await self._initialize()
  File "C:\Users\dorus\AppData\Local\Programs\Python\Python38\lib\site-packages\mpf\devices\driver.py", line 109, in _initialize
    raise AssertionError("Failed to configure driver {} in platform. See error above".format(self.name)) from e
AssertionError: Failed to configure driver c_popbumper_2 in platform. See error above
2022-10-16 17:09:22,284 : ERROR : asyncio : Task exception was never retrieved
future: <Task finished name='Task-11' coro=<SystemWideDevice.device_added_system_wide() done, defined at C:\Users\dorus\AppData\Local\Programs\Python\Python38\lib\site-packages\mpf\core\system_wide_device.py:15> exception=ConfigFileError('Failed to configure switch s_drop1 in platform. See error above')>
Traceback (most recent call last):
  File "C:\Users\dorus\AppData\Local\Programs\Python\Python38\lib\site-packages\mpf\devices\switch.py", line 148, in _initialize
    self.hw_switch = self.platform.configure_switch(
  File "C:\Users\dorus\AppData\Local\Programs\Python\Python38\lib\site-packages\mpf\platforms\opp\opp.py", line 825, in configure_switch
    number = self._get_dict_index(number)
  File "C:\Users\dorus\AppData\Local\Programs\Python\Python38\lib\site-packages\mpf\platforms\opp\opp.py", line 770, in _get_dict_index
    self.raise_config_error("Chain {} does not exist. Existing chains: {}".format(
  File "C:\Users\dorus\AppData\Local\Programs\Python\Python38\lib\site-packages\mpf\core\logging.py", line 172, in raise_config_error
    raise ConfigFileError(msg, error_no, self.log.name if self.log else "", context, self._url_base) \
mpf.exceptions.config_file_error.ConfigFileError: Config File Error in OPP: Chain 1 does not exist. Existing chains: ['COM7'] Error Code: CFE-OPP-3 (https://docs.missionpinball.org/en/0.55/logs/CFE-OPP-3.html)

The above exception was the direct cause of the following exception:

Traceback (most recent call last):
  File "C:\Users\dorus\AppData\Local\Programs\Python\Python38\lib\site-packages\mpf\core\system_wide_device.py", line 17, in device_added_system_wide
    await self._initialize()
  File "C:\Users\dorus\AppData\Local\Programs\Python\Python38\lib\site-packages\mpf\devices\switch.py", line 151, in _initialize
    raise ConfigFileError("Failed to configure switch {} in platform. See error above".format(self.name), 2,
mpf.exceptions.config_file_error.ConfigFileError: Config File Error in switch: Failed to configure switch s_drop1 in platform. See error above Error Code: CFE-switch-2 (https://docs.missionpinball.org/en/0.55/logs/CFE-switch-2.html)
2022-10-16 17:09:22,284 : ERROR : asyncio : Task exception was never retrieved
future: <Task finished name='Task-10' coro=<SystemWideDevice.device_added_system_wide() done, defined at C:\Users\dorus\AppData\Local\Programs\Python\Python38\lib\site-packages\mpf\core\system_wide_device.py:15> exception=ConfigFileError('Failed to configure switch s_trough_jam in platform. See error above')>
Traceback (most recent call last):
  File "C:\Users\dorus\AppData\Local\Programs\Python\Python38\lib\site-packages\mpf\devices\switch.py", line 148, in _initialize
    self.hw_switch = self.platform.configure_switch(
  File "C:\Users\dorus\AppData\Local\Programs\Python\Python38\lib\site-packages\mpf\platforms\opp\opp.py", line 825, in configure_switch
    number = self._get_dict_index(number)
  File "C:\Users\dorus\AppData\Local\Programs\Python\Python38\lib\site-packages\mpf\platforms\opp\opp.py", line 770, in _get_dict_index
    self.raise_config_error("Chain {} does not exist. Existing chains: {}".format(
  File "C:\Users\dorus\AppData\Local\Programs\Python\Python38\lib\site-packages\mpf\core\logging.py", line 172, in raise_config_error
    raise ConfigFileError(msg, error_no, self.log.name if self.log else "", context, self._url_base) \
mpf.exceptions.config_file_error.ConfigFileError: Config File Error in OPP: Chain 1 does not exist. Existing chains: ['COM7'] Error Code: CFE-OPP-3 (https://docs.missionpinball.org/en/0.55/logs/CFE-OPP-3.html)

The above exception was the direct cause of the following exception:

Traceback (most recent call last):
  File "C:\Users\dorus\AppData\Local\Programs\Python\Python38\lib\site-packages\mpf\core\system_wide_device.py", line 17, in device_added_system_wide
    await self._initialize()
  File "C:\Users\dorus\AppData\Local\Programs\Python\Python38\lib\site-packages\mpf\devices\switch.py", line 151, in _initialize
    raise ConfigFileError("Failed to configure switch {} in platform. See error above".format(self.name), 2,
mpf.exceptions.config_file_error.ConfigFileError: Config File Error in switch: Failed to configure switch s_trough_jam in platform. See error above Error Code: CFE-switch-2 (https://docs.missionpinball.org/en/0.55/logs/CFE-switch-2.html)
2022-10-16 17:09:22,284 : ERROR : asyncio : Task exception was never retrieved
future: <Task finished name='Task-35' coro=<SystemWideDevice.device_added_system_wide() done, defined at C:\Users\dorus\AppData\Local\Programs\Python\Python38\lib\site-packages\mpf\core\system_wide_device.py:15> exception=AssertionError('Failed to configure light l2 in platform. See error above')>
Traceback (most recent call last):
  File "C:\Users\dorus\AppData\Local\Programs\Python\Python38\lib\site-packages\mpf\devices\light.py", line 284, in _load_hw_driver
    return platform.configure_light(channel['number'], channel['subtype'], config, channel['platform_settings'])
  File "C:\Users\dorus\AppData\Local\Programs\Python\Python38\lib\site-packages\mpf\platforms\opp\opp.py", line 871, in configure_light
    self.raise_config_error("A request was made to configure an OPP neopixel "
  File "C:\Users\dorus\AppData\Local\Programs\Python\Python38\lib\site-packages\mpf\core\logging.py", line 172, in raise_config_error
    raise ConfigFileError(msg, error_no, self.log.name if self.log else "", context, self._url_base) \
mpf.exceptions.config_file_error.ConfigFileError: Config File Error in OPP: A request was made to configure an OPP neopixel with card number 1 which doesn't exist Error Code: CFE-OPP-10 (https://docs.missionpinball.org/en/0.55/logs/CFE-OPP-10.html)

The above exception was the direct cause of the following exception:

Traceback (most recent call last):
  File "C:\Users\dorus\AppData\Local\Programs\Python\Python38\lib\site-packages\mpf\core\system_wide_device.py", line 17, in device_added_system_wide
    await self._initialize()
  File "C:\Users\dorus\AppData\Local\Programs\Python\Python38\lib\site-packages\mpf\devices\light.py", line 313, in _initialize
    self._load_hw_drivers()
  File "C:\Users\dorus\AppData\Local\Programs\Python\Python38\lib\site-packages\mpf\devices\light.py", line 267, in _load_hw_drivers
    driver = self._load_hw_driver(channel, color)
  File "C:\Users\dorus\AppData\Local\Programs\Python\Python38\lib\site-packages\mpf\devices\light.py", line 286, in _load_hw_driver
    raise AssertionError("Failed to configure light {} in platform. See error above".
AssertionError: Failed to configure light l2 in platform. See error above
2022-10-16 17:09:22,284 : ERROR : asyncio : Task exception was never retrieved
future: <Task finished name='Task-23' coro=<SystemWideDevice.device_added_system_wide() done, defined at C:\Users\dorus\AppData\Local\Programs\Python\Python38\lib\site-packages\mpf\core\system_wide_device.py:15> exception=ConfigFileError('Failed to configure switch s_vukmid in platform. See error above')>
Traceback (most recent call last):
  File "C:\Users\dorus\AppData\Local\Programs\Python\Python38\lib\site-packages\mpf\devices\switch.py", line 148, in _initialize
    self.hw_switch = self.platform.configure_switch(
  File "C:\Users\dorus\AppData\Local\Programs\Python\Python38\lib\site-packages\mpf\platforms\opp\opp.py", line 825, in configure_switch
    number = self._get_dict_index(number)
  File "C:\Users\dorus\AppData\Local\Programs\Python\Python38\lib\site-packages\mpf\platforms\opp\opp.py", line 770, in _get_dict_index
    self.raise_config_error("Chain {} does not exist. Existing chains: {}".format(
  File "C:\Users\dorus\AppData\Local\Programs\Python\Python38\lib\site-packages\mpf\core\logging.py", line 172, in raise_config_error
    raise ConfigFileError(msg, error_no, self.log.name if self.log else "", context, self._url_base) \
mpf.exceptions.config_file_error.ConfigFileError: Config File Error in OPP: Chain 1 does not exist. Existing chains: ['COM7'] Error Code: CFE-OPP-3 (https://docs.missionpinball.org/en/0.55/logs/CFE-OPP-3.html)

The above exception was the direct cause of the following exception:

Traceback (most recent call last):
  File "C:\Users\dorus\AppData\Local\Programs\Python\Python38\lib\site-packages\mpf\core\system_wide_device.py", line 17, in device_added_system_wide
    await self._initialize()
  File "C:\Users\dorus\AppData\Local\Programs\Python\Python38\lib\site-packages\mpf\devices\switch.py", line 151, in _initialize
    raise ConfigFileError("Failed to configure switch {} in platform. See error above".format(self.name), 2,
mpf.exceptions.config_file_error.ConfigFileError: Config File Error in switch: Failed to configure switch s_vukmid in platform. See error above Error Code: CFE-switch-2 (https://docs.missionpinball.org/en/0.55/logs/CFE-switch-2.html)
2022-10-16 17:09:22,284 : ERROR : asyncio : Task exception was never retrieved
future: <Task finished name='Task-48' coro=<SystemWideDevice.device_added_system_wide() done, defined at C:\Users\dorus\AppData\Local\Programs\Python\Python38\lib\site-packages\mpf\core\system_wide_device.py:15> exception=ConfigFileError('Failed to configure switch s_start in platform. See error above')>
Traceback (most recent call last):
  File "C:\Users\dorus\AppData\Local\Programs\Python\Python38\lib\site-packages\mpf\devices\switch.py", line 148, in _initialize
    self.hw_switch = self.platform.configure_switch(
  File "C:\Users\dorus\AppData\Local\Programs\Python\Python38\lib\site-packages\mpf\platforms\opp\opp.py", line 825, in configure_switch
    number = self._get_dict_index(number)
  File "C:\Users\dorus\AppData\Local\Programs\Python\Python38\lib\site-packages\mpf\platforms\opp\opp.py", line 770, in _get_dict_index
    self.raise_config_error("Chain {} does not exist. Existing chains: {}".format(
  File "C:\Users\dorus\AppData\Local\Programs\Python\Python38\lib\site-packages\mpf\core\logging.py", line 172, in raise_config_error
    raise ConfigFileError(msg, error_no, self.log.name if self.log else "", context, self._url_base) \
mpf.exceptions.config_file_error.ConfigFileError: Config File Error in OPP: Chain 0 does not exist. Existing chains: ['COM7'] Error Code: CFE-OPP-3 (https://docs.missionpinball.org/en/0.55/logs/CFE-OPP-3.html)

The above exception was the direct cause of the following exception:

Traceback (most recent call last):
  File "C:\Users\dorus\AppData\Local\Programs\Python\Python38\lib\site-packages\mpf\core\system_wide_device.py", line 17, in device_added_system_wide
    await self._initialize()
  File "C:\Users\dorus\AppData\Local\Programs\Python\Python38\lib\site-packages\mpf\devices\switch.py", line 151, in _initialize
    raise ConfigFileError("Failed to configure switch {} in platform. See error above".format(self.name), 2,
mpf.exceptions.config_file_error.ConfigFileError: Config File Error in switch: Failed to configure switch s_start in platform. See error above Error Code: CFE-switch-2 (https://docs.missionpinball.org/en/0.55/logs/CFE-switch-2.html)
2022-10-16 17:09:22,284 : ERROR : asyncio : Task exception was never retrieved
future: <Task finished name='Task-60' coro=<SystemWideDevice.device_added_system_wide() done, defined at C:\Users\dorus\AppData\Local\Programs\Python\Python38\lib\site-packages\mpf\core\system_wide_device.py:15> exception=ConfigFileError('Failed to configure switch s_trough3 in platform. See error above')>
Traceback (most recent call last):
  File "C:\Users\dorus\AppData\Local\Programs\Python\Python38\lib\site-packages\mpf\devices\switch.py", line 148, in _initialize
    self.hw_switch = self.platform.configure_switch(
  File "C:\Users\dorus\AppData\Local\Programs\Python\Python38\lib\site-packages\mpf\platforms\opp\opp.py", line 825, in configure_switch
    number = self._get_dict_index(number)
  File "C:\Users\dorus\AppData\Local\Programs\Python\Python38\lib\site-packages\mpf\platforms\opp\opp.py", line 770, in _get_dict_index
    self.raise_config_error("Chain {} does not exist. Existing chains: {}".format(
  File "C:\Users\dorus\AppData\Local\Programs\Python\Python38\lib\site-packages\mpf\core\logging.py", line 172, in raise_config_error
    raise ConfigFileError(msg, error_no, self.log.name if self.log else "", context, self._url_base) \
mpf.exceptions.config_file_error.ConfigFileError: Config File Error in OPP: Chain 0 does not exist. Existing chains: ['COM7'] Error Code: CFE-OPP-3 (https://docs.missionpinball.org/en/0.55/logs/CFE-OPP-3.html)

The above exception was the direct cause of the following exception:

Traceback (most recent call last):
  File "C:\Users\dorus\AppData\Local\Programs\Python\Python38\lib\site-packages\mpf\core\system_wide_device.py", line 17, in device_added_system_wide
    await self._initialize()
  File "C:\Users\dorus\AppData\Local\Programs\Python\Python38\lib\site-packages\mpf\devices\switch.py", line 151, in _initialize
    raise ConfigFileError("Failed to configure switch {} in platform. See error above".format(self.name), 2,
mpf.exceptions.config_file_error.ConfigFileError: Config File Error in switch: Failed to configure switch s_trough3 in platform. See error above Error Code: CFE-switch-2 (https://docs.missionpinball.org/en/0.55/logs/CFE-switch-2.html)
2022-10-16 17:09:22,284 : INFO : EventManager : Event: ======'init_phase_2'====== Args={}
2022-10-16 17:09:22,284 : INFO : Machine : Starting the main run loop.
2022-10-16 17:09:22,294 : INFO : Machine : Shutting down...
2022-10-16 17:09:22,294 : INFO : EventManager : Event: ======'shutdown'====== Args={}
2022-10-16 17:09:22,294 : ERROR : OPP : Stop called on serial connection COM7
2022-10-16 17:09:22,294 : ERROR : asyncio : Task exception was never retrieved
future: <Task finished name='Task-73' coro=<SwitchController._initialize_switches() done, defined at C:\Users\dorus\AppData\Local\Programs\Python\Python38\lib\site-packages\mpf\core\switch_controller.py:80> exception=AttributeError("'NoneType' object has no attribute 'number'")>
Traceback (most recent call last):
  File "C:\Users\dorus\AppData\Local\Programs\Python\Python38\lib\site-packages\mpf\core\switch_controller.py", line 82, in _initialize_switches
    await self.update_switches_from_hw()
  File "C:\Users\dorus\AppData\Local\Programs\Python\Python38\lib\site-packages\mpf\core\switch_controller.py", line 104, in update_switches_from_hw
    switches.add((switch, switch.hw_switch.number))
AttributeError: 'NoneType' object has no attribute 'number'
2022-10-16 17:09:22,294 : ERROR : Machine : Runtime Exception
Traceback (most recent call last):
  File "C:\Users\dorus\AppData\Local\Programs\Python\Python38\lib\site-packages\mpf\devices\switch.py", line 148, in _initialize
    self.hw_switch = self.platform.configure_switch(
  File "C:\Users\dorus\AppData\Local\Programs\Python\Python38\lib\site-packages\mpf\platforms\opp\opp.py", line 825, in configure_switch
    number = self._get_dict_index(number)
  File "C:\Users\dorus\AppData\Local\Programs\Python\Python38\lib\site-packages\mpf\platforms\opp\opp.py", line 770, in _get_dict_index
    self.raise_config_error("Chain {} does not exist. Existing chains: {}".format(
  File "C:\Users\dorus\AppData\Local\Programs\Python\Python38\lib\site-packages\mpf\core\logging.py", line 172, in raise_config_error
    raise ConfigFileError(msg, error_no, self.log.name if self.log else "", context, self._url_base) \
mpf.exceptions.config_file_error.ConfigFileError: Config File Error in OPP: Chain 1 does not exist. Existing chains: ['COM7'] Error Code: CFE-OPP-3 (https://docs.missionpinball.org/en/0.55/logs/CFE-OPP-3.html)

The above exception was the direct cause of the following exception:

Traceback (most recent call last):
  File "C:\Users\dorus\AppData\Local\Programs\Python\Python38\lib\site-packages\mpf\core\machine.py", line 769, in _run_loop
    raise self._exception['exception']
  File "C:\Users\dorus\AppData\Local\Programs\Python\Python38\lib\site-packages\mpf\core\system_wide_device.py", line 17, in device_added_system_wide
    await self._initialize()
  File "C:\Users\dorus\AppData\Local\Programs\Python\Python38\lib\site-packages\mpf\devices\switch.py", line 151, in _initialize
    raise ConfigFileError("Failed to configure switch {} in platform. See error above".format(self.name), 2,
mpf.exceptions.config_file_error.ConfigFileError: Config File Error in switch: Failed to configure switch s_toplane3 in platform. See error above Error Code: CFE-switch-2 (https://docs.missionpinball.org/en/0.55/logs/CFE-switch-2.html)
2022-10-16 17:09:22,430 : INFO : crash_reporter : Will not report crash as "report_crashes" mode is "never"
2022-10-16 17:09:22,430 : INFO : root : MPF run loop ended.
