2022-08-25 19:11:08,565 : INFO : root : Loading config.
2022-08-25 19:11:08,568 : INFO : YamlMultifileConfigLoader : Machine config file #1: config.yaml
2022-08-25 19:11:08,568 : INFO : ConfigProcessor : Loading config from cache: C:\Users\dorus\AppData\Local\Temp\b5a61368077cb638a2d30584b4c214a4.mpf_cache
2022-08-25 19:11:08,645 : WARNING : ConfigProcessor : Config file in cache changed: C:\pinball\MPFTest\modes\attract\config\attract.yaml
2022-08-25 19:11:08,646 : INFO : ConfigProcessor : Loading config from file c:\users\dorus\appdata\local\programs\python\python38\lib\site-packages\mpf\modes\attract\config\attract.yaml.
2022-08-25 19:11:08,647 : INFO : ConfigProcessor : Loading config: c:\users\dorus\appdata\local\programs\python\python38\lib\site-packages\mpf\modes\attract\config\attract.yaml
2022-08-25 19:11:08,647 : INFO : ConfigProcessor : Loading config from file C:\pinball\MPFTest\modes\attract\config\attract.yaml.
2022-08-25 19:11:08,648 : INFO : ConfigProcessor : Loading config: C:\pinball\MPFTest\modes\attract\config\attract.yaml
2022-08-25 19:11:08,649 : INFO : ConfigProcessor : Config file cache created: C:\Users\dorus\AppData\Local\Temp\f669821a9dd3c682462b30511846254b.mpf_cache
2022-08-25 19:11:08,649 : INFO : ConfigProcessor : Loading config from cache: C:\Users\dorus\AppData\Local\Temp\12b32bb22730f14b6d64b890cf6dd15e.mpf_cache
2022-08-25 19:11:08,650 : INFO : ConfigProcessor : Loading config from cache: C:\Users\dorus\AppData\Local\Temp\9fc873ed955b120383c74823d9b2df21.mpf_cache
2022-08-25 19:11:08,651 : INFO : Machine : Mission Pinball Framework Core Engine v0.55.0
2022-08-25 19:11:08,651 : INFO : Machine : Command line arguments: {'no_load_cache': False, 'create_config_cache': True, 'bcp': True, 'configfile': ['config.yaml'], 'force_assets_load': False, 'jsonlogging': False, 'logfile': 'logs\\2022-08-25-19-11-08-mpf-LAPTOP-AS8QDAQG.log', 'pause': False, 'production': False, 'text_ui': True, 'loglevel': 15, 'consoleloglevel': 20, 'force_platform': None, 'syslog_address': None, 'mc_file_name': None, 'no_sound': False}
2022-08-25 19:11:08,651 : INFO : Machine : MPF path: c:\users\dorus\appdata\local\programs\python\python38\lib\site-packages\mpf
2022-08-25 19:11:08,651 : INFO : Machine : Machine path: C:\pinball\MPFTest
2022-08-25 19:11:08,651 : INFO : Machine : Platform: win32
2022-08-25 19:11:08,651 : INFO : Machine : Python executable location: c:\users\dorus\appdata\local\programs\python\python38\python.exe
2022-08-25 19:11:08,651 : INFO : Machine : Python version: 3.8.10 (64-bit)
2022-08-25 19:11:08,653 : INFO : Machine : Initialise MPF.
2022-08-25 19:11:08,798 : INFO : OPP : Connecting to COM7 at 115200bps
2022-08-25 19:11:08,884 : INFO : OPP : Init of OPP board COM7 done
2022-08-25 19:11:08,885 : INFO : EventManager : Event: ======'machine_var_credits_string'====== Args={'value': 'FREE PLAY', 'prev_value': None, 'change': True}
2022-08-25 19:11:08,940 : INFO : EventManager : Event: ======'machine_var_master_volume'====== Args={'value': 0.5, 'prev_value': None, 'change': True}
2022-08-25 19:11:08,940 : INFO : EventManager : Event: ======'machine_var_mpf_version'====== Args={'value': 'MPF v0.55.0', 'prev_value': None, 'change': True}
2022-08-25 19:11:08,940 : INFO : EventManager : Event: ======'machine_var_mpf_extended_version'====== Args={'value': 'MPF v0.55.0, Config version:5, Show version: 5, BCP version:1.1', 'prev_value': None, 'change': True}
2022-08-25 19:11:08,940 : INFO : EventManager : Event: ======'machine_var_python_version'====== Args={'value': '3.8.10', 'prev_value': None, 'change': True}
2022-08-25 19:11:08,952 : INFO : EventManager : Event: ======'machine_var_platform'====== Args={'value': 'Windows-10-10.0.19044-SP0', 'prev_value': None, 'change': True}
2022-08-25 19:11:08,952 : INFO : EventManager : Event: ======'machine_var_platform_system'====== Args={'value': 'Windows', 'prev_value': None, 'change': True}
2022-08-25 19:11:08,952 : INFO : EventManager : Event: ======'machine_var_platform_release'====== Args={'value': '10', 'prev_value': None, 'change': True}
2022-08-25 19:11:08,952 : INFO : EventManager : Event: ======'machine_var_platform_version'====== Args={'value': '10.0.19044', 'prev_value': None, 'change': True}
2022-08-25 19:11:08,952 : INFO : EventManager : Event: ======'machine_var_platform_machine'====== Args={'value': 'AMD64', 'prev_value': None, 'change': True}
2022-08-25 19:11:08,952 : INFO : EventManager : Event: ======'init_phase_1'====== Args={}
2022-08-25 19:11:08,961 : INFO : EventManager : Event: ======'init_phase_2'====== Args={}
2022-08-25 19:11:08,962 : INFO : EventManager : Event: ======'bcp_connection_attempt'====== Args={'name': 'local_display', 'host': 'localhost', 'port': 5050}
2022-08-25 19:11:08,964 : INFO : BCPClientSocket : Connecting BCP to 'local_display' at localhost:5050...
2022-08-25 19:11:10,986 : INFO : BCPClientSocket : Connected BCP to 'local_display' localhost:5050
2022-08-25 19:11:10,988 : INFO : EventManager : Event: ======'bcp_clients_connected'====== Args={}
2022-08-25 19:11:11,044 : INFO : EventManager : Event: ======'init_phase_3'====== Args={}
2022-08-25 19:11:11,051 : INFO : EventManager : Event: ======'init_phase_4'====== Args={}
2022-08-25 19:11:11,051 : INFO : EventManager : Event: ======'machine_var_mc_version'====== Args={'value': 'MPF-MC v0.55.0', 'prev_value': None, 'change': True}
2022-08-25 19:11:11,052 : INFO : EventManager : Event: ======'machine_var_mc_extended_version'====== Args={'value': 'MPF-MC v0.55.0 (config_version=5, BCP v1.1, Requires MPF v0.55.0-dev.49)', 'prev_value': None, 'change': True}
2022-08-25 19:11:11,060 : INFO : EventManager : Event: ======'machine_var_audits_events_game_started'====== Args={'value': 0, 'prev_value': None, 'change': True}
2022-08-25 19:11:11,060 : INFO : EventManager : Event: ======'machine_var_audits_events_game_ended'====== Args={'value': 0, 'prev_value': None, 'change': True}
2022-08-25 19:11:11,060 : INFO : EventManager : Event: ======'machine_var_audits_player_score'====== Args={'value': {'top': [], 'average': 0, 'total': 0}, 'prev_value': None, 'change': True}
2022-08-25 19:11:11,061 : INFO : EventManager : Event: ======'init_phase_5'====== Args={}
2022-08-25 19:11:11,065 : INFO : EventManager : Event: ======'init_done'====== Args={}
2022-08-25 19:11:11,066 : INFO : EventManager : Event: ======'machine_reset_phase_1'====== Args={}
2022-08-25 19:11:11,078 : INFO : EventManager : Event: ======'machine_reset_phase_2'====== Args={}
2022-08-25 19:11:11,078 : INFO : EventManager : Event: ======'machine_reset_phase_3'====== Args={}
2022-08-25 19:11:11,079 : INFO : EventManager : Event: ======'reset_complete'====== Args={}
2022-08-25 19:11:11,079 : INFO : EventManager : Event: ======'mode_attract_will_start'====== Args={}
2022-08-25 19:11:11,080 : INFO : EventManager : Event: ======'mode_attract_starting'====== Args={}
2022-08-25 19:11:11,080 : INFO : Mode.attract : Started. Priority: 10
2022-08-25 19:11:11,080 : INFO : EventManager : Event: ======'modes_active_modes_changed'====== Args={}
2022-08-25 19:11:11,080 : INFO : EventManager : Event: ======'mode_attract_started'====== Args={}
2022-08-25 19:11:11,080 : ERROR : asyncio : Exception in callback EventManager.process_event_queue()
handle: <Handle EventManager.process_event_queue()>
Traceback (most recent call last):
  File "c:\users\dorus\appdata\local\programs\python\python38\lib\site-packages\mpf\core\show_controller.py", line 128, in replace_or_advance_show
    show_obj = self.machine.shows[config.name]
KeyError: 'attract_display_loop'

During handling of the above exception, another exception occurred:

Traceback (most recent call last):
  File "c:\users\dorus\appdata\local\programs\python\python38\lib\site-packages\mpf\core\events.py", line 695, in _run_handlers
    result = handler.callback(**merged_kwargs)
  File "c:\users\dorus\appdata\local\programs\python\python38\lib\site-packages\mpf\core\config_player.py", line 328, in config_play_callback
    return self.play(settings=settings, context=context, calling_context=calling_context, priority=priority,
  File "c:\users\dorus\appdata\local\programs\python\python38\lib\site-packages\mpf\config_players\show_player.py", line 60, in play
    self._update_show(show.name, show_settings, context, queue, start_time, show_tokens)
  File "c:\users\dorus\appdata\local\programs\python\python38\lib\site-packages\mpf\config_players\show_player.py", line 224, in _update_show
    action(key, instance_dict, show_name, show_settings, queue, start_time, placeholder_args)
  File "c:\users\dorus\appdata\local\programs\python\python38\lib\site-packages\mpf\config_players\show_player.py", line 116, in _play
    instance_dict[key] = self.machine.show_controller.replace_or_advance_show(previous_show, show_config,
  File "c:\users\dorus\appdata\local\programs\python\python38\lib\site-packages\mpf\core\show_controller.py", line 130, in replace_or_advance_show
    raise KeyError("Cannot play show '{}'. No show with that "
KeyError: "Cannot play show 'attract_display_loop'. No show with that name."

The above exception was the direct cause of the following exception:

Traceback (most recent call last):
  File "c:\users\dorus\appdata\local\programs\python\python38\lib\asyncio\events.py", line 81, in _run
    self._context.run(self._callback, *self._args)
  File "c:\users\dorus\appdata\local\programs\python\python38\lib\site-packages\mpf\core\events.py", line 779, in process_event_queue
    self._process_event(event=event[0],
  File "c:\users\dorus\appdata\local\programs\python\python38\lib\site-packages\mpf\core\events.py", line 741, in _process_event
    result = self._run_handlers(event, ev_type, kwargs)
  File "c:\users\dorus\appdata\local\programs\python\python38\lib\site-packages\mpf\core\events.py", line 697, in _run_handlers
    raise Exception("Exception while processing {} for event {}. {}".format(handler, event, e)) from e
Exception: Exception while processing RegisteredHandler(callback=<bound method ConfigPlayer.config_play_callback of ConfigPlayer.show_player/shows>, priority=10, kwargs={'calling_context': 'mode_attract_started', 'mode': <Mode.attract>, 'settings': {attract_display_loop-None-None: {'priority': 0, 'action': 'play', 'show': None, 'speed': 1.0, 'block_queue': False, 'start_step': <NativeTemplate 1>, 'start_running': <Template True>, 'loops': -1, 'sync_ms': None, 'manual_advance': False, 'show_queue': None, 'key': None, 'show_tokens': {}, 'events_when_played': [], 'events_when_stopped': [], 'events_when_looped': [], 'events_when_paused': [], 'events_when_resumed': [], 'events_when_advanced': [], 'events_when_stepped_back': [], 'events_when_updated': [], 'events_when_completed': []}}}, key=UUID('6eb647f2-f0c9-4625-a269-93cbe58ebfbb'), condition=None, blocking_facility=None) for event mode_attract_started. "Cannot play show 'attract_display_loop'. No show with that name."
2022-08-25 19:11:11,082 : INFO : Machine : Starting the main run loop.
2022-08-25 19:11:11,084 : INFO : Machine : Shutting down...
2022-08-25 19:11:11,084 : INFO : EventManager : Event: ======'shutdown'====== Args={}
2022-08-25 19:11:11,085 : ERROR : OPP : Stop called on serial connection COM7
2022-08-25 19:11:11,087 : ERROR : Machine : Runtime Exception
Traceback (most recent call last):
  File "c:\users\dorus\appdata\local\programs\python\python38\lib\site-packages\mpf\core\show_controller.py", line 128, in replace_or_advance_show
    show_obj = self.machine.shows[config.name]
KeyError: 'attract_display_loop'

During handling of the above exception, another exception occurred:

Traceback (most recent call last):
  File "c:\users\dorus\appdata\local\programs\python\python38\lib\site-packages\mpf\core\events.py", line 695, in _run_handlers
    result = handler.callback(**merged_kwargs)
  File "c:\users\dorus\appdata\local\programs\python\python38\lib\site-packages\mpf\core\config_player.py", line 328, in config_play_callback
    return self.play(settings=settings, context=context, calling_context=calling_context, priority=priority,
  File "c:\users\dorus\appdata\local\programs\python\python38\lib\site-packages\mpf\config_players\show_player.py", line 60, in play
    self._update_show(show.name, show_settings, context, queue, start_time, show_tokens)
  File "c:\users\dorus\appdata\local\programs\python\python38\lib\site-packages\mpf\config_players\show_player.py", line 224, in _update_show
    action(key, instance_dict, show_name, show_settings, queue, start_time, placeholder_args)
  File "c:\users\dorus\appdata\local\programs\python\python38\lib\site-packages\mpf\config_players\show_player.py", line 116, in _play
    instance_dict[key] = self.machine.show_controller.replace_or_advance_show(previous_show, show_config,
  File "c:\users\dorus\appdata\local\programs\python\python38\lib\site-packages\mpf\core\show_controller.py", line 130, in replace_or_advance_show
    raise KeyError("Cannot play show '{}'. No show with that "
KeyError: "Cannot play show 'attract_display_loop'. No show with that name."

The above exception was the direct cause of the following exception:

Traceback (most recent call last):
  File "c:\users\dorus\appdata\local\programs\python\python38\lib\site-packages\mpf\core\machine.py", line 769, in _run_loop
    raise self._exception['exception']
  File "c:\users\dorus\appdata\local\programs\python\python38\lib\asyncio\events.py", line 81, in _run
    self._context.run(self._callback, *self._args)
  File "c:\users\dorus\appdata\local\programs\python\python38\lib\site-packages\mpf\core\events.py", line 779, in process_event_queue
    self._process_event(event=event[0],
  File "c:\users\dorus\appdata\local\programs\python\python38\lib\site-packages\mpf\core\events.py", line 741, in _process_event
    result = self._run_handlers(event, ev_type, kwargs)
  File "c:\users\dorus\appdata\local\programs\python\python38\lib\site-packages\mpf\core\events.py", line 697, in _run_handlers
    raise Exception("Exception while processing {} for event {}. {}".format(handler, event, e)) from e
Exception: Exception while processing RegisteredHandler(callback=<bound method ConfigPlayer.config_play_callback of ConfigPlayer.show_player/shows>, priority=10, kwargs={'calling_context': 'mode_attract_started', 'mode': <Mode.attract>, 'settings': {attract_display_loop-None-None: {'priority': 0, 'action': 'play', 'show': None, 'speed': 1.0, 'block_queue': False, 'start_step': <NativeTemplate 1>, 'start_running': <Template True>, 'loops': -1, 'sync_ms': None, 'manual_advance': False, 'show_queue': None, 'key': None, 'show_tokens': {}, 'events_when_played': [], 'events_when_stopped': [], 'events_when_looped': [], 'events_when_paused': [], 'events_when_resumed': [], 'events_when_advanced': [], 'events_when_stepped_back': [], 'events_when_updated': [], 'events_when_completed': []}}}, key=UUID('6eb647f2-f0c9-4625-a269-93cbe58ebfbb'), condition=None, blocking_facility=None) for event mode_attract_started. "Cannot play show 'attract_display_loop'. No show with that name."
2022-08-25 19:11:11,205 : INFO : crash_reporter : Will not report crash as "report_crashes" mode is "never"
2022-08-25 19:11:11,206 : INFO : root : MPF run loop ended.
